Workbook

Sheet Sheet1
A1: 00:02:47,280 --> 00:02:54,680 | E1: A1 | F1: 46007.228 | G1: =LEFT(A1, 8) -> 00:02:47 | H1: =LEFT(TRIM(MID(A1, FIND("-->", A1)+3, 20)), 8) -> 00:02:54 | I1: =A2 -> الله. أعاده. عليكم السلام ورحمة الله وبركاته.
A2: الله. أعاده. عليكم السلام ورحمة الله وبركاته. | E2: A3 | F2: =TIME(HOUR(F1), MINUTE(F1), SECOND(F1)) -> 0.22777778 | G2: =LEFT(A2, 8) -> الله. أع | H2: =LEFT(TRIM(MID(A2, FIND("-->", A2)+3, 20)), 8) -> #VALUE! | I2: =A3 -> 0
G3: =LEFT(A3, 8) | H3: =LEFT(TRIM(MID(A3, FIND("-->", A3)+3, 20)), 8) -> #VALUE! | I3: =A4 -> 00:02:58,240 --> 00:03:14,360
A4: 00:02:58,240 --> 00:03:14,360 | G4: =LEFT(A4, 8) -> 00:02:58 | H4: =LEFT(TRIM(MID(A4, FIND("-->", A4)+3, 20)), 8) -> 00:03:14 | I4: =A5 -> حياكم الله يا أحباب. وعليكم السلام ورحمة الله وبركاته. جمعة. يا الله. فيض بطل.
A5: حياكم الله يا أحباب. وعليكم السلام ورحمة الله وبركاته. جمعة. يا الله. فيض بطل. | G5: =LEFT(A5, 8) -> حياكم ا | H5: =LEFT(TRIM(MID(A5, FIND("-->", A5)+3, 20)), 8) -> #VALUE! | I5: =A6 -> 0
G6: =LEFT(A6, 8) | H6: =LEFT(TRIM(MID(A6, FIND("-->", A6)+3, 20)), 8) -> #VALUE! | I6: =A7 -> 00:03:16,440 --> 00:03:23,640
A7: 00:03:16,440 --> 00:03:23,640 | G7: =LEFT(A7, 8) -> 00:03:16 | H7: =LEFT(TRIM(MID(A7, FIND("-->", A7)+3, 20)), 8) -> 00:03:23 | I7: =A8 -> معي. وكذا. ان شاء الله. يضبط. ما هذا؟ الحد؟ الصفحة. مالك.
A8: معي. وكذا. ان شاء الله. يضبط. ما هذا؟ الحد؟ الصفحة. مالك. | G8: =LEFT(A8, 8) -> معي. وكذ | H8: =LEFT(TRIM(MID(A8, FIND("-->", A8)+3, 20)), 8) -> #VALUE! | I8: =A9 -> 0
G9: =LEFT(A9, 8) | H9: =LEFT(TRIM(MID(A9, FIND("-->", A9)+3, 20)), 8) -> #VALUE! | I9: =A10 -> 00:03:25,860 --> 00:03:29,579
A10: 00:03:25,860 --> 00:03:29,579 | G10: =LEFT(A10, 8) -> 00:03:25 | H10: =LEFT(TRIM(MID(A10, FIND("-->", A10)+3, 20)), 8) -> 00:03:29 | I10: =A11 -> احنا نشرب.
A11: احنا نشرب. | G11: =LEFT(A11, 8) -> احنا نشر | H11: =LEFT(TRIM(MID(A11, FIND("-->", A11)+3, 20)), 8) -> #VALUE! | I11: =A12 -> 0
G12: =LEFT(A12, 8) | H12: =LEFT(TRIM(MID(A12, FIND("-->", A12)+3, 20)), 8) -> #VALUE! | I12: =A13 -> 00:03:29,579 --> 00:04:57,090
A13: 00:03:29,579 --> 00:04:57,090 | G13: =LEFT(A13, 8) -> 00:03:29 | H13: =LEFT(TRIM(MID(A13, FIND("-->", A13)+3, 20)), 8) -> 00:04:57 | I13: =A14 -> الزوت. لا. الله اكبر. واحد. واحد.
A14: الزوت. لا. الله اكبر. واحد. واحد. | G14: =LEFT(A14, 8) -> الزوت. ل | H14: =LEFT(TRIM(MID(A14, FIND("-->", A14)+3, 20)), 8) -> #VALUE! | I14: =A15 -> 0
G15: =LEFT(A15, 8) | H15: =LEFT(TRIM(MID(A15, FIND("-->", A15)+3, 20)), 8) -> #VALUE! | I15: =A16 -> 00:04:57,090 --> 00:04:57,090
A16: 00:04:57,090 --> 00:04:57,090 | G16: =LEFT(A16, 8) -> 00:04:57 | H16: =LEFT(TRIM(MID(A16, FIND("-->", A16)+3, 20)), 8) -> 00:04:57 | I16: =A17 -> واحد.
A17: واحد. | G17: =LEFT(A17, 8) -> واحد. | H17: =LEFT(TRIM(MID(A17, FIND("-->", A17)+3, 20)), 8) -> #VALUE! | I17: =A18 -> 0
G18: =LEFT(A18, 8) | H18: =LEFT(TRIM(MID(A18, FIND("-->", A18)+3, 20)), 8) -> #VALUE! | I18: =A19 -> 00:04:57,090 --> 00:04:57,090
A19: 00:04:57,090 --> 00:04:57,090 | G19: =LEFT(A19, 8) -> 00:04:57 | H19: =LEFT(TRIM(MID(A19, FIND("-->", A19)+3, 20)), 8) -> 00:04:57 | I19: =A20 -> واحد.
A20: واحد. | G20: =LEFT(A20, 8) -> واحد. | H20: =LEFT(TRIM(MID(A20, FIND("-->", A20)+3, 20)), 8) -> #VALUE! | I20: =A21 -> 0
G21: =LEFT(A21, 8) | H21: =LEFT(TRIM(MID(A21, FIND("-->", A21)+3, 20)), 8) -> #VALUE! | I21: =A22 -> 00:04:57,090 --> 00:04:57,090
A22: 00:04:57,090 --> 00:04:57,090 | G22: =LEFT(A22, 8) -> 00:04:57 | H22: =LEFT(TRIM(MID(A22, FIND("-->", A22)+3, 20)), 8) -> 00:04:57 | I22: =A23 -> واحد.
A23: واحد. | G23: =LEFT(A23, 8) -> واحد. | H23: =LEFT(TRIM(MID(A23, FIND("-->", A23)+3, 20)), 8) -> #VALUE! | I23: =A24 -> 0
G24: =LEFT(A24, 8) | H24: =LEFT(TRIM(MID(A24, FIND("-->", A24)+3, 20)), 8) -> #VALUE! | I24: =A25 -> 00:04:57,090 --> 00:04:57,090
A25: 00:04:57,090 --> 00:04:57,090 | G25: =LEFT(A25, 8) -> 00:04:57 | H25: =LEFT(TRIM(MID(A25, FIND("-->", A25)+3, 20)), 8) -> 00:04:57 | I25: =A26 -> واحد.
A26: واحد. | G26: =LEFT(A26, 8) -> واحد. | H26: =LEFT(TRIM(MID(A26, FIND("-->", A26)+3, 20)), 8) -> #VALUE! | I26: =A27 -> 0
G27: =LEFT(A27, 8) | H27: =LEFT(TRIM(MID(A27, FIND("-->", A27)+3, 20)), 8) -> #VALUE! | I27: =A28 -> 00:04:57,090 --> 00:04:57,500
A28: 00:04:57,090 --> 00:04:57,500 | G28: =LEFT(A28, 8) -> 00:04:57 | H28: =LEFT(TRIM(MID(A28, FIND("-->", A28)+3, 20)), 8) -> 00:04:57 | I28: =A29 -> واحد. واحد.
A29: واحد. واحد. | G29: =LEFT(A29, 8) -> واحد. وا | H29: =LEFT(TRIM(MID(A29, FIND("-->", A29)+3, 20)), 8) -> #VALUE! | I29: =A30 -> 0
G30: =LEFT(A30, 8) | H30: =LEFT(TRIM(MID(A30, FIND("-->", A30)+3, 20)), 8) -> #VALUE! | I30: =A31 -> 00:04:57,500 --> 00:04:57,510
A31: 00:04:57,500 --> 00:04:57,510 | G31: =LEFT(A31, 8) -> 00:04:57 | H31: =LEFT(TRIM(MID(A31, FIND("-->", A31)+3, 20)), 8) -> 00:04:57 | I31: =A32 -> واحد. واحد.
A32: واحد. واحد. | G32: =LEFT(A32, 8) -> واحد. وا | H32: =LEFT(TRIM(MID(A32, FIND("-->", A32)+3, 20)), 8) -> #VALUE! | I32: =A33 -> 0
G33: =LEFT(A33, 8) | H33: =LEFT(TRIM(MID(A33, FIND("-->", A33)+3, 20)), 8) -> #VALUE! | I33: =A34 -> 00:04:57,510 --> 00:04:57,510
A34: 00:04:57,510 --> 00:04:57,510 | G34: =LEFT(A34, 8) -> 00:04:57 | H34: =LEFT(TRIM(MID(A34, FIND("-->", A34)+3, 20)), 8) -> 00:04:57 | I34: =A35 -> واحد. واحد. واحد.
A35: واحد. واحد. واحد. | G35: =LEFT(A35, 8) -> واحد. وا | H35: =LEFT(TRIM(MID(A35, FIND("-->", A35)+3, 20)), 8) -> #VALUE! | I35: =A36 -> 0
G36: =LEFT(A36, 8) | H36: =LEFT(TRIM(MID(A36, FIND("-->", A36)+3, 20)), 8) -> #VALUE! | I36: =A37 -> 00:04:57,510 --> 00:05:08,260
A37: 00:04:57,510 --> 00:05:08,260 | G37: =LEFT(A37, 8) -> 00:04:57 | H37: =LEFT(TRIM(MID(A37, FIND("-->", A37)+3, 20)), 8) -> 00:05:08 | I37: =A38 -> واحد. واحد. راح نبدأ ان شاء الله دقيقة بس. اقل من دقيقة ان شاء الله راح نبدأ بس ننتظر مزيد من الطلاب. الصوت ان شاء الله واضح الحين.
A38: واحد. واحد. راح نبدأ ان شاء الله دقيقة بس. اقل من دقيقة ان شاء الله راح نبدأ بس ننتظر مزيد من الطلاب. الصوت ان شاء الله واضح الحين. | G38: =LEFT(A38, 8) -> واحد. وا | H38: =LEFT(TRIM(MID(A38, FIND("-->", A38)+3, 20)), 8) -> #VALUE! | I38: =A39 -> 0
G39: =LEFT(A39, 8) | H39: =LEFT(TRIM(MID(A39, FIND("-->", A39)+3, 20)), 8) -> #VALUE! | I39: =A40 -> 00:05:08,260 --> 00:05:17,900
A40: 00:05:08,260 --> 00:05:17,900 | G40: =LEFT(A40, 8) -> 00:05:08 | H40: =LEFT(TRIM(MID(A40, FIND("-->", A40)+3, 20)), 8) -> 00:05:17 | I40: =A41 -> هو كذا بداية الحصة يا فارس لكن ياخذ وقت وتضبط الامور ان شاء الله.
...

Sheet 70690 transcript
A1: {=INDEX(Sheet1!$G:$G, ROW()*3 - 2)+Sheet1!$F$2} -> 0.22971065 | B1: {=INDEX(Sheet1!$H:$H, ROW()*3 - 2)+Sheet1!$F$2} -> 0.22979167 | C1: {=INDEX(Sheet1!$I:$I, ROW()*3 - 2)} -> الله. أعاده. عليكم السلام ورحمة الله وبركاته.
A2: {=INDEX(Sheet1!$G:$G, ROW()*3 - 2)+Sheet1!$F$2} -> 0.22983796 | B2: {=INDEX(Sheet1!$H:$H, ROW()*3 - 2)+Sheet1!$F$2} -> 0.23002315 | C2: {=INDEX(Sheet1!$I:$I, ROW()*3 - 2)} -> حياكم الله يا أحباب. وعليكم السلام ورحمة الله وبركاته. جمعة. يا الله. فيض بطل.
A3: {=INDEX(Sheet1!$G:$G, ROW()*3 - 2)+Sheet1!$F$2} -> 0.2300463 | B3: {=INDEX(Sheet1!$H:$H, ROW()*3 - 2)+Sheet1!$F$2} -> 0.23012731 | C3: {=INDEX(Sheet1!$I:$I, ROW()*3 - 2)} -> معي. وكذا. ان شاء الله. يضبط. ما هذا؟ الحد؟ الصفحة. مالك.
A4: {=INDEX(Sheet1!$G:$G, ROW()*3 - 2)+Sheet1!$F$2} -> 0.23015046 | B4: {=INDEX(Sheet1!$H:$H, ROW()*3 - 2)+Sheet1!$F$2} -> 0.23019676 | C4: {=INDEX(Sheet1!$I:$I, ROW()*3 - 2)} -> احنا نشرب.
A5: {=INDEX(Sheet1!$G:$G, ROW()*3 - 2)+Sheet1!$F$2} -> 0.23019676 | B5: {=INDEX(Sheet1!$H:$H, ROW()*3 - 2)+Sheet1!$F$2} -> 0.23121528 | C5: {=INDEX(Sheet1!$I:$I, ROW()*3 - 2)} -> الزوت. لا. الله اكبر. واحد. واحد.
A6: {=INDEX(Sheet1!$G:$G, ROW()*3 - 2)+Sheet1!$F$2} -> 0.23121528 | B6: {=INDEX(Sheet1!$H:$H, ROW()*3 - 2)+Sheet1!$F$2} -> 0.23121528 | C6: {=INDEX(Sheet1!$I:$I, ROW()*3 - 2)} -> واحد.
A7: {=INDEX(Sheet1!$G:$G, ROW()*3 - 2)+Sheet1!$F$2} -> 0.23121528 | B7: {=INDEX(Sheet1!$H:$H, ROW()*3 - 2)+Sheet1!$F$2} -> 0.23121528 | C7: {=INDEX(Sheet1!$I:$I, ROW()*3 - 2)} -> واحد.
A8: {=INDEX(Sheet1!$G:$G, ROW()*3 - 2)+Sheet1!$F$2} -> 0.23121528 | B8: {=INDEX(Sheet1!$H:$H, ROW()*3 - 2)+Sheet1!$F$2} -> 0.23121528 | C8: {=INDEX(Sheet1!$I:$I, ROW()*3 - 2)} -> واحد.
A9: {=INDEX(Sheet1!$G:$G, ROW()*3 - 2)+Sheet1!$F$2} -> 0.23121528 | B9: {=INDEX(Sheet1!$H:$H, ROW()*3 - 2)+Sheet1!$F$2} -> 0.23121528 | C9: {=INDEX(Sheet1!$I:$I, ROW()*3 - 2)} -> واحد.
A10: {=INDEX(Sheet1!$G:$G, ROW()*3 - 2)+Sheet1!$F$2} -> 0.23121528 | B10: {=INDEX(Sheet1!$H:$H, ROW()*3 - 2)+Sheet1!$F$2} -> 0.23121528 | C10: {=INDEX(Sheet1!$I:$I, ROW()*3 - 2)} -> واحد. واحد.
A11: {=INDEX(Sheet1!$G:$G, ROW()*3 - 2)+Sheet1!$F$2} -> 0.23121528 | B11: {=INDEX(Sheet1!$H:$H, ROW()*3 - 2)+Sheet1!$F$2} -> 0.23121528 | C11: {=INDEX(Sheet1!$I:$I, ROW()*3 - 2)} -> واحد. واحد.
A12: {=INDEX(Sheet1!$G:$G, ROW()*3 - 2)+Sheet1!$F$2} -> 0.23121528 | B12: {=INDEX(Sheet1!$H:$H, ROW()*3 - 2)+Sheet1!$F$2} -> 0.23121528 | C12: {=INDEX(Sheet1!$I:$I, ROW()*3 - 2)} -> واحد. واحد. واحد.
... A116: {=INDEX(Sheet1!$G:$G, ROW()*3 - 2)+Sheet1!$F$2} -> 0.24592593 | B116: {=INDEX(Sheet1!$H:$H, ROW()*3 - 2)+Sheet1!$F$2} -> 0.2459838 | C116: {=INDEX(Sheet1!$I:$I, ROW()*3 - 2)} -> طه اي ممتاز. طيب مساحة المضلل.

Sheet f_user_session_70690
A1: user_id | B1: user_name | C1: user_type | D1: user_sentiment | E1: course_session_class_type | F1: room_id | G1: course_session_id | H1: teacher_start_datetime | I1: teacher_end_datetime | J1: teaching_time | K1: session_time | L1: room_open_time | M1: room_end_time | N1: user_enter_time | O1: user_exit_time | P1: entered_room | Q1: room_time | R1: learning_time | S1: lobby_before_time | T1: lobby_after_time | U1: lobby_time | V1: active_time | W1: total_polls_seen | X1: total_polls_responded | Y1: total_messages | Z1: total_hand_raise | AA1: total_unmutes | AB1: total_video_on | AC1: platforms | AD1: device_ids | AE1: feature_active_duration | AF1: feature_active_duration_during_activity | AG1: course_id | AH1: teacher_id | AI1: is_course_session_teacher | AJ1: country_ids | AK1: country_names | AL1: classroom_name | AM1: classroom_description | AN1: classroom_join_code | AO1: dt
A2: 646320 | B2: ÿ£. ÿ≠ÿ≥ŸÜ ÿ≥ÿπŸäÿØ | C2: FACILITATOR | E2: LIVE_CLASS | F2: 54332 | G2: 70690 | H2: 46007.228 | I2: 46007.263 | J2: 49.98 | K2: 49.98 | L2: 46007.219 | M2: 46007.263 | N2: 46007.23 | O2: 46007.254 | P2: 8 | Q2: 8.7 | R2: 8.7 | S2: 0 | T2: 0 | U2: 0 | V2: 0 | Y2: 0 | Z2: 0 | AA2: 0 | AB2: 0 | AC2: ["web"] | AD2: ["7f3454c9-30c0-4fad-9a08-01387b9f765c"] | AG2: 14796 | AH2: 636745 | AI2: 0 | AJ2: [2] | AK2: ["Saudi Arabia"] | AL2: ÿ£. ÿ≠ÿ≥ŸÜ ÿ®ŸÜ ÿ≥ÿπŸäÿØ | AN2: YH2L | AO2: 20251216
A3: 647496 | B3: ÿ®ÿØÿ± ÿßŸÑÿ≠ÿ±ÿ®Ÿä | C3: STUDENT | D3: positive | E3: LIVE_CLASS | F3: 54332 | G3: 70690 | H3: 46007.228 | I3: 46007.263 | J3: 49.98 | K3: 49.98 | L3: 46007.219 | M3: 46007.263 | N3: 46007.23 | O3: 46007.263 | P3: 2 | Q3: 47.28 | R3: 47.28 | S3: 0 | T3: 0 | U3: 0 | V3: 11.07 | W3: 13 | X3: 13 | Y3: 0 | Z3: 0 | AA3: 0 | AB3: 0 | AC3: ["android"] | AD3: ["95e2a56f-6eff-4a08-8927-2d22d3102298"] | AE3: {"ACTIVITY_START":579680,"REACTION":120000} | AF3: {} | AG3: 14796 | AH3: 636745 | AI3: 0 | AJ3: [2] | AK3: ["Saudi Arabia"] | AL3: ÿ£. ÿπÿ®ÿØÿßŸÑÿ±ÿ≠ŸÖŸÜ ÿßŸÑÿ≥ÿßŸÑŸÖŸä | AN3: 7B3M | AO3: 20251216
A4: 647504 | B4: ÿπÿ®ÿØÿßŸÑŸÖÿ¨ŸäÿØ ÿßŸÑÿ≠ŸÖŸàÿØ | C4: STUDENT | D4: positive | E4: LIVE_CLASS | F4: 54332 | G4: 70690 | H4: 46007.228 | I4: 46007.263 | J4: 49.98 | K4: 49.98 | L4: 46007.219 | M4: 46007.263 | N4: 46007.229 | O4: 46007.263 | P4: 2 | Q4: 48.8 | R4: 48.8 | S4: 0 | T4: 0 | U4: 0 | V4: 6.18 | W4: 1 | X4: 1 | Y4: 0 | Z4: 0 | AA4: 0 | AB4: 0 | AC4: ["android"] | AD4: ["dbe830c2-59d6-401b-9c08-c691e5087fd8"] | AE4: {"TEAM_CHEER":300000,"REACTION":30000,"SLIDE_PREVIEW":7513,"ACTIVITY_START":65405} | AF4: {"1396625":{"REACTION":30000,"SLIDE_PREVIEW":7513}} | AG4: 14796 | AH4: 636745 | AI4: 0 | AJ4: [2] | AK4: ["Saudi Arabia"] | AL4: ÿ£. ÿπÿ®ÿØÿßŸÑÿπÿ≤Ÿäÿ≤ ÿßŸÑŸÖŸàÿ≥Ÿâ | AN4: PG2Q | AO4: 20251216
A5: 652934 | B5: ÿπÿ®ÿØÿßŸÑŸÑŸá ÿßŸÑŸáÿßÿ¨ÿ±Ÿä | C5: STUDENT | D5: positive | E5: LIVE_CLASS | F5: 54332 | G5: 70690 | H5: 46007.228 | I5: 46007.263 | J5: 49.98 | K5: 49.98 | L5: 46007.219 | M5: 46007.263 | N5: 46007.229 | O5: 46007.26 | P5: 1 | Q5: 45.05 | R5: 45.05 | S5: 0 | T5: 0 | U5: 0 | V5: 14.07 | W5: 12 | X5: 12 | Y5: 6 | Z5: 0 | AA5: 0 | AB5: 0 | AC5: ["android"] | AD5: ["e2b772d1-809d-4ec2-bb25-a7e2df012367"] | AE5: {"REACTION":180000,"TEAM_CHEER":300000,"MESSAGE":163420,"ACTIVITY_START":313644,"ZOOM_IN":20135} | AF5: {"1396620":{"ZOOM_IN":20135}} | AG5: 14796 | AH5: 636745 | AI5: 0 | AJ5: [2] | AK5: ["Saudi Arabia"] | AL5: ÿ£. ÿπÿ®ÿØÿßŸÑÿ±ÿ≠ŸÖŸÜ ÿßŸÑÿ≥ÿßŸÑŸÖŸä | AN5: 7B3M | AO5: 20251216
A6: 652929 | B6: ÿ±ŸäÿßŸÜ ÿßŸÑÿπŸÜŸÇÿ±Ÿä | C6: STUDENT | D6: positive | E6: LIVE_CLASS | F6: 54332 | G6: 70690 | H6: 46007.228 | I6: 46007.263 | J6: 49.98 | K6: 49.98 | L6: 46007.219 | M6: 46007.263 | N6: 46007.23 | O6: 46007.263 | P6: 1 | Q6: 47.8 | R6: 47.8 | S6: 0 | T6: 0 | U6: 0 | V6: 19.03 | W6: 0 | X6: 0 | Y6: 0 | Z6: 0 | AA6: 0 | AB6: 0 | AC6: ["android"] | AD6: ["09a93964-5cf0-4615-b62b-366ad77185c1"] | AE6: {"TEAM_CHEER":300000,"ACTIVITY_START":811808,"REACTION":30000} | AF6: {} | AG6: 14796 | AH6: 636745 | AI6: 0 | AJ6: [2] | AK6: ["Saudi Arabia"] | AL6: ÿ£. ÿπÿ®ÿØÿßŸÑÿπÿ≤Ÿäÿ≤ ÿßŸÑŸÖŸàÿ≥Ÿâ | AN6: PG2Q | AO6: 20251216
A7: 652958 | B7: ŸÅŸáÿØ ÿßŸÑÿ±ÿ¥ŸäÿØŸä | C7: STUDENT | D7: positive | E7: LIVE_CLASS | F7: 54332 | G7: 70690 | H7: 46007.228 | I7: 46007.263 | J7: 49.98 | K7: 49.98 | L7: 46007.219 | M7: 46007.263 | N7: 46007.24 | O7: 46007.258 | P7: 9 | Q7: 19.07 | R7: 19.07 | S7: 0 | T7: 0 | U7: 0 | V7: 4.66 | W7: 8 | X7: 8 | Y7: 1 | Z7: 0 | AA7: 0 | AB7: 0 | AC7: ["android"] | AD7: ["a4faffea-3ef9-466b-b9b0-399e0c4990cf"] | AE7: {"ACTIVITY_START":197635,"REACTION":90000,"MESSAGE":28659} | AF7: {} | AG7: 14796 | AH7: 636745 | AI7: 0 | AJ7: [2] | AK7: ["Saudi Arabia"] | AL7: RHM-IKM-111 | AM7: ÿ£. ÿπÿ®ÿØÿßŸÑŸÑŸá ÿßŸÑÿ¥ŸÖÿ±Ÿä | AN7: 8MNK | AO7: 20251216
A8: 647404 | B8: ÿÆÿßŸÑÿØ ÿßŸÑÿ¨ÿ¥ | C8: STUDENT | D8: positive | E8: LIVE_CLASS | F8: 54332 | G8: 70690 | H8: 46007.228 | I8: 46007.263 | J8: 49.98 | K8: 49.98 | L8: 46007.219 | M8: 46007.263 | N8: 46007.229 | O8: 46007.263 | P8: 2 | Q8: 44 | R8: 44 | S8: 0 | T8: 0 | U8: 0 | V8: 17.35 | W8: 11 | X8: 11 | Y8: 0 | Z8: 1 | AA8: 1 | AB8: 0 | AC8: ["android"] | AD8: ["65830221-da14-4e38-8124-e241262d33df"] | AE8: {"TEAM_CHEER":300000,"REACTION":180000,"ACTIVITY_START":454267,"MESSAGE":60000,"STUDENT_CHEER":30000,"STAGE_TIME":127655,"ZOOM_IN":60491} | AF8: {"1396621":{"ZOOM_IN":60491}} | AG8: 14796 | AH8: 636745 | AI8: 0 | AJ8: [2] | AK8: ["Saudi Arabia"] | AL8: ÿ£. ÿ≠ÿ≥ŸÜ ÿ®ŸÜ ÿ≥ÿπŸäÿØ | AN8: YH2L | AO8: 20251216
A9: 647411 | B9: ŸÅÿßÿ±ÿ≥ ÿπŸàÿ∂Ÿá | C9: STUDENT | D9: neutral | E9: LIVE_CLASS | F9: 54332 | G9: 70690 | H9: 46007.228 | I9: 46007.263 | J9: 49.98 | K9: 49.98 | L9: 46007.219 | M9: 46007.263 | N9: 46007.229 | O9: 46007.259 | P9: 10 | Q9: 41.22 | R9: 41.22 | S9: 0 | T9: 0 | U9: 0 | V9: 23.63 | W9: 9 | X9: 9 | Y9: 14 | Z9: 5 | AA9: 8 | AB9: 0 | AC9: ["android"] | AD9: ["5414dcf2-886e-469c-a5db-aad7f21e6648"] | AE9: {"REACTION":265783,"TEAM_CHEER":295713,"MESSAGE":680725,"ACTIVITY_START":457438,"STAGE_TIME":213802,"STUDENT_CHEER":60000,"SLIDE_PREVIEW":5629,"ZOOM_IN":19620} | AF9: {} | AG9: 14796 | AH9: 636745 | AI9: 0 | AJ9: [2] | AK9: ["Saudi Arabia"] | AL9: ÿ£. ÿ≠ÿ≥ŸÜ ÿ®ŸÜ ÿ≥ÿπŸäÿØ | AN9: YH2L | AO9: 20251216
A10: 646388 | B10: ÿ£. ŸÜŸàÿßŸÅ ÿßŸÑŸÇŸÖŸäÿπ | C10: FACILITATOR | E10: LIVE_CLASS | F10: 54332 | G10: 70690 | H10: 46007.228 | I10: 46007.263 | J10: 49.98 | K10: 49.98 | L10: 46007.219 | M10: 46007.263 | N10: 46007.219 | O10: 46007.234 | P10: 2 | Q10: 0.33 | R10: 0.22 | S10: 0.12 | T10: 0 | U10: 0.12 | V10: 0 | Y10: 0 | Z10: 0 | AA10: 0 | AB10: 0 | AC10: ["web"] | AD10: ["367892a3-19bb-4418-bde9-5e058b26207f"] | AG10: 14796 | AH10: 636745 | AI10: 0 | AJ10: [2] | AK10: ["Saudi Arabia"] | AL10: ÿ£. ŸÜŸàÿßŸÅ ÿßŸÑŸÇŸÖŸäÿπ | AN10: 2WXQ | AO10: 20251216
A11: 647295 | B11: ŸÖÿ≠ŸÖÿØ ÿßŸÑŸÅŸàÿßÿ≤ | C11: STUDENT | D11: positive | E11: LIVE_CLASS | F11: 54332 | G11: 70690 | H11: 46007.228 | I11: 46007.263 | J11: 49.98 | K11: 49.98 | L11: 46007.219 | M11: 46007.263 | N11: 46007.224 | O11: 46007.263 | P11: 2 | Q11: 49.25 | R11: 44.13 | S11: 5.12 | T11: 0 | U11: 5.12 | V11: 1.49 | W11: 0 | X11: 0 | Y11: 0 | Z11: 0 | AA11: 0 | AB11: 0 | AC11: ["android"] | AD11: ["8e906e0b-6a9d-4bfe-b7cc-06f260532b34"] | AE11: {"ZOOM_IN":59487,"REACTION":30000} | AF11: {} | AG11: 14796 | AH11: 636745 | AI11: 0 | AJ11: [2] | AK11: ["Saudi Arabia"] | AL11: ÿ£. ŸÜŸàÿßŸÅ ÿßŸÑŸÇŸÖŸäÿπ | AN11: 2WXQ | AO11: 20251216
A12: 652940 | B12: ŸÅŸáÿØ ÿßŸÑÿØÿ∫Ÿäÿ¥ŸÖ | C12: STUDENT | E12: LIVE_CLASS | F12: 54332 | G12: 70690 | H12: 46007.228 | I12: 46007.263 | J12: 49.98 | K12: 49.98 | L12: 46007.219 | M12: 46007.263 | N12: 46007.241 | O12: 46007.26 | P12: 1 | Q12: 27.2 | R12: 27.2 | S12: 0 | T12: 0 | U12: 0 | V12: 5.51 | W12: 6 | X12: 6 | Y12: 0 | Z12: 0 | AA12: 0 | AB12: 0 | AC12: ["android"] | AD12: ["50a635f8-bae7-49e8-8993-106961e25a67"] | AE12: {"ACTIVITY_START":253897,"REACTION":90000,"ZOOM_IN":52413} | AF12: {"1396621":{"ZOOM_IN":52413}} | AG12: 14796 | AH12: 636745 | AI12: 0 | AJ12: [2] | AK12: ["Saudi Arabia"] | AL12: ÿ£. ÿπÿ®ÿØÿßŸÑÿ±ÿ≠ŸÖŸÜ ÿßŸÑÿ≥ÿßŸÑŸÖŸä | AN12: 7B3M | AO12: 20251216
A13: 647426 | B13: ÿπÿ®ÿØÿßŸÑŸÑŸá ÿ≥ÿπÿØ ÿßŸÑŸÇÿ≠ÿ∑ÿßŸÜŸä | C13: STUDENT | D13: neutral | E13: LIVE_CLASS | F13: 54332 | G13: 70690 | H13: 46007.228 | I13: 46007.263 | J13: 49.98 | K13: 49.98 | L13: 46007.219 | M13: 46007.263 | N13: 46007.23 | O13: 46007.261 | P13: 3 | Q13: 44.63 | R13: 44.63 | S13: 0 | T13: 0 | U13: 0 | V13: 11.75 | W13: 13 | X13: 13 | Y13: 3 | Z13: 0 | AA13: 0 | AB13: 0 | AC13: ["android"] | AD13: ["7f163fb4-fb87-4d03-964b-70d7547a59bd"] | AE13: {"STUDENT_CHEER":24630,"MESSAGE":78700,"ACTIVITY_START":507329,"REACTION":120000,"ZOOM_IN":62970} | AF13: {"1396621":{"ZOOM_IN":31780},"1396620":{"ZOOM_IN":31190}} | AG13: 14796 | AH13: 636745 | AI13: 0 | AJ13: [2] | AK13: ["Saudi Arabia"] | AL13: ÿ£. ÿ≠ÿ≥ŸÜ ÿ®ŸÜ ÿ≥ÿπŸäÿØ | AN13: YH2L | AO13: 20251216
A14: 679059 | B14: ÿßÿ≠ŸÖÿØ ÿßŸÑÿ≤Ÿáÿ±ÿßŸÜŸä | C14: FACILITATOR | E14: LIVE_CLASS | F14: 54332 | G14: 70690 | H14: 46007.228 | I14: 46007.263 | J14: 49.98 | K14: 49.98 | L14: 46007.219 | M14: 46007.263 | N14: 46007.233 | O14: 46007.262 | P14: 16 | Q14: 28.93 | R14: 28.93 | S14: 0 | T14: 0 | U14: 0 | V14: 0 | Y14: 0 | Z14: 0 | AA14: 0 | AB14: 0 | AC14: ["web"] | AD14: ["de90334e-7d64-4d85-81b7-50af23946099"] | AG14: 14796 | AH14: 636745 | AI14: 0 | AJ14: [2] | AK14: ["Saudi Arabia"] | AL14: ÿßÿ≠ŸÖÿØ ÿßŸÑÿ≤Ÿáÿ±ÿßŸÜŸä | AM14: ÿßÿ≠ŸÖÿØ ÿßŸÑÿ≤Ÿáÿ±ÿßŸÜŸä | AN14: 8UQ4 | AO14: 20251216
A15: 648953 | B15: ÿπÿ®ÿØÿßŸÑÿπÿ≤Ÿäÿ≤ ÿßŸÑŸÖŸÜŸÇŸàÿ± | C15: STUDENT | D15: positive | E15: LIVE_CLASS | F15: 54332 | G15: 70690 | H15: 46007.228 | I15: 46007.263 | J15: 49.98 | K15: 49.98 | L15: 46007.219 | M15: 46007.263 | N15: 46007.23 | O15: 46007.263 | P15: 2 | Q15: 48.13 | R15: 48.13 | S15: 0 | T15: 0 | U15: 0 | V15: 12.45 | W15: 11 | X15: 11 | Y15: 0 | Z15: 0 | AA15: 0 | AB15: 0 | AC15: ["android"] | AD15: ["92b728f3-4db6-4a7e-bda7-7fbf4bc26c67"] | AE15: {"TEAM_CHEER":296043,"REACTION":150000,"ACTIVITY_START":338694} | AF15: {} | AG15: 14796 | AH15: 636745 | AI15: 0 | AJ15: [2] | AK15: ["Saudi Arabia"] | AL15: ÿ£. ŸÜŸàÿßŸÅ ÿßŸÑŸÇŸÖŸäÿπ | AN15: 2WXQ | AO15: 20251216
A16: 648951 | B16: ÿ•ÿ®ÿ±ÿßŸáŸäŸÖ ÿ®ŸÜ ÿØÿßŸäŸÑ | C16: STUDENT | D16: neutral | E16: LIVE_CLASS | F16: 54332 | G16: 70690 | H16: 46007.228 | I16: 46007.263 | J16: 49.98 | K16: 49.98 | L16: 46007.219 | M16: 46007.263 | N16: 46007.255 | O16: 46007.263 | P16: 1 | Q16: 11.95 | R16: 11.95 | S16: 0 | T16: 0 | U16: 0 | V16: 4.08 | W16: 8 | X16: 8 | Y16: 1 | Z16: 0 | AA16: 0 | AB16: 0 | AC16: ["android"] | AD16: ["1bd1d401-d4bd-4272-ba1f-c0d26794966d"] | AE16: {"ZOOM_IN":35595,"ACTIVITY_START":155497,"REACTION":45147,"MESSAGE":30000} | AF16: {"1396621":{"ZOOM_IN":35595}} | AG16: 14796 | AH16: 636745 | AI16: 0 | AJ16: [2] | AK16: ["Saudi Arabia"] | AL16: ÿ£. ŸÜŸàÿßŸÅ ÿßŸÑŸÇŸÖŸäÿπ | AN16: 2WXQ | AO16: 20251216
A17: 657525 | B17: ŸÅŸáÿØ ÿßŸÑÿ≥ŸÜŸäÿØŸä | C17: STUDENT | D17: negative | E17: LIVE_CLASS | F17: 54332 | G17: 70690 | H17: 46007.228 | I17: 46007.263 | J17: 49.98 | K17: 49.98 | L17: 46007.219 | M17: 46007.263 | N17: 46007.23 | O17: 46007.263 | P17: 1 | Q17: 47.8 | R17: 47.8 | S17: 0 | T17: 0 | U17: 0 | V17: 17.26 | W17: 13 | X17: 13 | Y17: 4 | Z17: 1 | AA17: 0 | AB17: 0 | AC17: ["android"] | AD17: ["0ac96dc8-bafa-4afa-b682-3d2243a37634"] | AE17: {"TEAM_CHEER":300000,"MESSAGE":180000,"SLIDE_PREVIEW":3880,"ACTIVITY_START":562145,"REACTION":120000,"ZOOM_IN":65636} | AF17: {"1396625":{"SLIDE_PREVIEW":3880}} | AG17: 14796 | AH17: 636745 | AI17: 0 | AJ17: [2] | AK17: ["Saudi Arabia"] | AL17: ÿ£. ÿπÿ®ÿØÿßŸÑÿ±ÿ≠ŸÖŸÜ ÿßŸÑÿ≥ÿßŸÑŸÖŸä | AN17: 7B3M | AO17: 20251216
A18: 647306 | B18: ŸäŸàÿ≥ŸÅ ÿßŸÑÿ≠ÿ±ÿ®Ÿä | C18: STUDENT | D18: positive | E18: LIVE_CLASS | F18: 54332 | G18: 70690 | H18: 46007.228 | I18: 46007.263 | J18: 49.98 | K18: 49.98 | L18: 46007.219 | M18: 46007.263 | N18: 46007.247 | O18: 46007.263 | P18: 1 | Q18: 22.68 | R18: 22.68 | S18: 0 | T18: 0 | U18: 0 | V18: 8.48 | W18: 10 | X18: 10 | Y18: 1 | Z18: 0 | AA18: 0 | AB18: 0 | AC18: ["android"] | AD18: ["368a6cee-8e52-45e7-9db0-e52987b377e5"] | AE18: {"SLIDE_PREVIEW":48324,"ACTIVITY_START":382429,"REACTION":60000,"MESSAGE":30000} | AF18: {"1396622":{"SLIDE_PREVIEW":48324}} | AG18: 14796 | AH18: 636745 | AI18: 0 | AJ18: [2] | AK18: ["Saudi Arabia"] | AL18: ÿ£. ŸÜŸàÿßŸÅ ÿßŸÑŸÇŸÖŸäÿπ | AN18: 2WXQ | AO18: 20251216
A19: 648986 | B19: ÿ®ŸÜÿØÿ± ÿßŸÑÿ∫ÿßŸÖÿØŸä | C19: STUDENT | D19: positive | E19: LIVE_CLASS | F19: 54332 | G19: 70690 | H19: 46007.228 | I19: 46007.263 | J19: 49.98 | K19: 49.98 | L19: 46007.219 | M19: 46007.263 | N19: 46007.231 | O19: 46007.263 | P19: 1 | Q19: 46.75 | R19: 46.75 | S19: 0 | T19: 0 | U19: 0 | V19: 15.39 | W19: 4 | X19: 4 | Y19: 0 | Z19: 0 | AA19: 0 | AB19: 0 | AC19: ["android"] | AD19: ["0bd75702-8eeb-4042-8089-d5ef884987d5"] | AE19: {"ACTIVITY_START":811808,"REACTION":120000,"ZOOM_IN":23335} | AF19: {"1396620":{"ZOOM_IN":23335}} | AG19: 14796 | AH19: 636745 | AI19: 0 | AJ19: [2] | AK19: ["Saudi Arabia"] | AL19: ÿ£. ÿ≠ÿ≥ŸÜ ÿ®ŸÜ ÿ≥ÿπŸäÿØ | AN19: YH2L | AO19: 20251216
A20: 636745 | B20: ÿ£.ÿπÿ®ÿØÿßŸÑÿ±ÿ≤ÿßŸÇ ÿßŸÑÿ¥ÿ±ŸäŸÅ | C20: TEACHER | E20: LIVE_CLASS | F20: 54332 | G20: 70690 | H20: 46007.228 | I20: 46007.263 | J20: 49.98 | K20: 49.98 | L20: 46007.219 | M20: 46007.263 | N20: 46007.228 | O20: 46007.263 | P20: 3 | Q20: 49.98 | R20: 49.98 | Y20: 1 | AA20: 1 | AB20: 3 | AC20: ["web"] | AD20: ["745c9fea-e435-4d9f-88e4-86c5df3192fc"] | AG20: 14796 | AH20: 636745 | AI20: 1 | AJ20: [2] | AK20: ["Saudi Arabia"] | AO20: 20251216
A21: 647433 | B21: ŸÅŸäÿµŸÑ ÿßŸÑÿ®ÿ¥ÿ±Ÿä | C21: STUDENT | D21: positive | E21: LIVE_CLASS | F21: 54332 | G21: 70690 | H21: 46007.228 | I21: 46007.263 | J21: 49.98 | K21: 49.98 | L21: 46007.219 | M21: 46007.263 | N21: 46007.23 | O21: 46007.263 | P21: 1 | Q21: 47.23 | R21: 47.23 | S21: 0 | T21: 0 | U21: 0 | V21: 12.92 | W21: 13 | X21: 13 | Y21: 0 | Z21: 1 | AA21: 0 | AB21: 0 | AC21: ["android"] | AD21: ["22af8b0d-c940-45a8-ab6e-26ba1e5ba793"] | AE21: {"SLIDE_PREVIEW":13888,"ACTIVITY_START":654730,"REACTION":150000,"MESSAGE":60000} | AF21: {"1396625":{"SLIDE_PREVIEW":13888}} | AG21: 14796 | AH21: 636745 | AI21: 0 | AJ21: [2] | AK21: ["Saudi Arabia"] | AL21: ÿ£. ÿ≠ÿ≥ŸÜ ÿ®ŸÜ ÿ≥ÿπŸäÿØ | AN21: YH2L | AO21: 20251216
A22: 647499 | B22: ÿπÿ®ÿØÿßŸÑÿ±ÿ≠ŸÖŸÜ ÿßŸÑÿ∫ÿßŸÜŸÖ | C22: STUDENT | D22: positive | E22: LIVE_CLASS | F22: 54332 | G22: 70690 | H22: 46007.228 | I22: 46007.263 | J22: 49.98 | K22: 49.98 | L22: 46007.219 | M22: 46007.263 | N22: 46007.234 | O22: 46007.263 | P22: 4 | Q22: 40.83 | R22: 40.83 | S22: 0 | T22: 0 | U22: 0 | V22: 9.49 | W22: 13 | X22: 13 | Y22: 2 | Z22: 0 | AA22: 0 | AB22: 0 | AC22: ["android"] | AD22: ["b73d08aa-3984-43c2-a1fa-748b8b6e5b1d"] | AE22: {"ACTIVITY_START":428898,"REACTION":120000,"MESSAGE":60000,"ZOOM_IN":35883} | AF22: {"1396620":{"ZOOM_IN":35883}} | AG22: 14796 | AH22: 636745 | AI22: 0 | AJ22: [2] | AK22: ["Saudi Arabia"] | AL22: ÿ£. ÿπÿ®ÿØÿßŸÑÿ±ÿ≠ŸÖŸÜ ÿßŸÑÿ≥ÿßŸÑŸÖŸä | AN22: 7B3M | AO22: 20251216
A23: 647748 | B23: ÿπÿ®ÿØÿßŸÑÿπÿ≤Ÿäÿ≤ ÿßŸÑÿπŸÖÿßÿ± | C23: STUDENT | D23: positive | E23: LIVE_CLASS | F23: 54332 | G23: 70690 | H23: 46007.228 | I23: 46007.263 | J23: 49.98 | K23: 49.98 | L23: 46007.219 | M23: 46007.263 | N23: 46007.229 | O23: 46007.263 | P23: 3 | Q23: 47.47 | R23: 47.47 | S23: 0 | T23: 0 | U23: 0 | V23: 17.64 | W23: 10 | X23: 10 | Y23: 1 | Z23: 0 | AA23: 0 | AB23: 0 | AC23: ["android"] | AD23: ["372a279a-00a0-48df-8157-2a72479d7028"] | AE23: {"REACTION":150000,"TEAM_CHEER":301159,"ZOOM_IN":142897,"ACTIVITY_START":582283,"MESSAGE":30000} | AF23: {"1396623":{"ZOOM_IN":30000},"1396621":{"ZOOM_IN":81987}} | AG23: 14796 | AH23: 636745 | AI23: 0 | AJ23: [2] | AK23: ["Saudi Arabia"] | AL23: RHM-IKM-111 | AM23: ÿ£. ÿπÿ®ÿØÿßŸÑŸÑŸá ÿßŸÑÿ¥ŸÖÿ±Ÿä | AN23: 8MNK | AO23: 20251216
A24: 660350 | B24: ÿ£. ÿπÿ®ÿØÿßŸÑÿ±ÿ≠ŸÖŸÜ ÿßŸÑÿ≥ÿßŸÑŸÖŸä | C24: FACILITATOR | E24: LIVE_CLASS | F24: 54332 | G24: 70690 | H24: 46007.228 | I24: 46007.263 | J24: 49.98 | K24: 49.98 | L24: 46007.219 | M24: 46007.263 | N24: 46007.23 | O24: 46007.263 | P24: 11 | Q24: 25.82 | R24: 25.82 | S24: 0 | T24: 0 | U24: 0 | V24: 0 | Y24: 0 | Z24: 0 | AA24: 0 | AB24: 0 | AC24: ["web"] | AD24: ["fa9a2258-f8af-4b25-beff-8afd3afe841b"] | AG24: 14796 | AH24: 636745 | AI24: 0 | AJ24: [2] | AK24: ["Saudi Arabia"] | AL24: ÿ£. ÿπÿ®ÿØÿßŸÑÿ±ÿ≠ŸÖŸÜ ÿßŸÑÿ≥ÿßŸÑŸÖŸä | AN24: 7B3M | AO24: 20251216
A25: 652938 | B25: ŸäŸàÿ≥ŸÅ ÿßŸÑÿ∫ŸÜÿßŸÖ | C25: STUDENT | D25: positive | E25: LIVE_CLASS | F25: 54332 | G25: 70690 | H25: 46007.228 | I25: 46007.263 | J25: 49.98 | K25: 49.98 | L25: 46007.219 | M25: 46007.263 | N25: 46007.231 | O25: 46007.263 | P25: 1 | Q25: 45.38 | R25: 45.38 | S25: 0 | T25: 0 | U25: 0 | V25: 14.03 | W25: 0 | X25: 0 | Y25: 0 | Z25: 0 | AA25: 0 | AB25: 0 | AC25: ["android"] | AD25: ["95c070ab-3722-46dd-9569-a1f69794944a"] | AE25: {"ACTIVITY_START":811808,"REACTION":30000} | AF25: {} | AG25: 14796 | AH25: 636745 | AI25: 0 | AJ25: [2] | AK25: ["Saudi Arabia"] | AL25: ÿ£. ÿπÿ®ÿØÿßŸÑÿ±ÿ≠ŸÖŸÜ ÿßŸÑÿ≥ÿßŸÑŸÖŸä | AN25: 7B3M | AO25: 20251216
A26: 651452 | B26: Ÿäÿßÿ≥ÿ± ÿßŸÑÿØŸàÿ≥ÿ±Ÿä | C26: STUDENT | D26: positive | E26: LIVE_CLASS | F26: 54332 | G26: 70690 | H26: 46007.228 | I26: 46007.263 | J26: 49.98 | K26: 49.98 | L26: 46007.219 | M26: 46007.263 | N26: 46007.232 | O26: 46007.263 | P26: 1 | Q26: 45.28 | R26: 45.28 | S26: 0 | T26: 0 | U26: 0 | V26: 15.12 | W26: 13 | X26: 13 | Y26: 2 | Z26: 1 | AA26: 0 | AB26: 0 | AC26: ["android"] | AD26: ["deda385c-a9bf-406f-8118-7e47f3d92240"] | AE26: {"ACTIVITY_START":443288,"REACTION":150000,"MESSAGE":120000,"TEAM_CHEER":300000} | AF26: {} | AG26: 14796 | AH26: 636745 | AI26: 0 | AJ26: [2] | AK26: ["Saudi Arabia"] | AL26: ÿ£. ÿπÿ®ÿØÿßŸÑÿ±ÿ≠ŸÖŸÜ ÿßŸÑÿ≥ÿßŸÑŸÖŸä | AN26: 7B3M | AO26: 20251216
A27: 647739 | B27: ÿπÿ®ÿØÿßŸÑÿ±ÿ≠ŸÖŸÜ ÿßŸÑÿ≤Ÿáÿ±ÿßŸÜŸä | C27: STUDENT | D27: positive | E27: LIVE_CLASS | F27: 54332 | G27: 70690 | H27: 46007.228 | I27: 46007.263 | J27: 49.98 | K27: 49.98 | L27: 46007.219 | M27: 46007.263 | N27: 46007.255 | O27: 46007.263 | P27: 2 | Q27: 11.27 | R27: 11.27 | S27: 0 | T27: 0 | U27: 0 | V27: 4.94 | W27: 9 | X27: 9 | Y27: 0 | Z27: 0 | AA27: 0 | AB27: 0 | AC27: ["android"] | AD27: ["2169ae16-1a3e-4c5a-9c32-8ae2a703372b"] | AE27: {"ACTIVITY_START":234965,"ZOOM_IN":80991} | AF27: {"1396620":{"ZOOM_IN":80991}} | AG27: 14796 | AH27: 636745 | AI27: 0 | AJ27: [2] | AK27: ["Saudi Arabia"] | AL27: RHM-IKM-111 | AM27: ÿ£. ÿπÿ®ÿØÿßŸÑŸÑŸá ÿßŸÑÿ¥ŸÖÿ±Ÿä | AN27: 8MNK | AO27: 20251216
A28: 652933 | B28: ŸÅŸáÿØ ÿßŸÑÿ≥ŸÜŸäÿØŸä | C28: STUDENT | E28: LIVE_CLASS | F28: 54332 | G28: 70690 | H28: 46007.228 | I28: 46007.263 | J28: 49.98 | K28: 49.98 | L28: 46007.219 | M28: 46007.263 | N28: 46007.256 | O28: 46007.263 | P28: 1 | Q28: 10.33 | R28: 10.33 | S28: 0 | T28: 0 | U28: 0 | V28: 5.01 | W28: 4 | X28: 4 | Y28: 0 | Z28: 0 | AA28: 0 | AB28: 0 | AC28: ["android"] | AD28: ["79ee445a-a091-4c84-9a14-c0f7045b5205"] | AE28: {"ACTIVITY_START":300406} | AF28: {} | AG28: 14796 | AH28: 636745 | AI28: 0 | AJ28: [2] | AK28: ["Saudi Arabia"] | AL28: ÿ£. ÿπÿ®ÿØÿßŸÑÿ±ÿ≠ŸÖŸÜ ÿßŸÑÿ≥ÿßŸÑŸÖŸä | AN28: 7B3M | AO28: 20251216
A29: 648959 | B29: ŸÉÿ±ŸÖ ÿ∫ŸÜÿßŸäŸÖ | C29: STUDENT | D29: neutral | E29: LIVE_CLASS | F29: 54332 | G29: 70690 | H29: 46007.228 | I29: 46007.263 | J29: 49.98 | K29: 49.98 | L29: 46007.219 | M29: 46007.263 | N29: 46007.229 | O29: 46007.262 | P29: 2 | Q29: 47.45 | R29: 47.45 | S29: 0 | T29: 0 | U29: 0 | V29: 20.71 | W29: 13 | X29: 13 | Y29: 6 | Z29: 1 | AA29: 6 | AB29: 0 | AC29: ["android"] | AD29: ["8d59d01c-2c48-4bcd-9557-8765d5ea2e5f"] | AE29: {"REACTION":180000,"TEAM_CHEER":300000,"MESSAGE":222287,"SLIDE_PREVIEW":18140,"ACTIVITY_START":493979,"ZOOM_IN":224359,"STAGE_TIME":112955,"STUDENT_CHEER":30000} | AF29: {"1396625":{"SLIDE_PREVIEW":10136},"1396620":{"ZOOM_IN":69921}} | AG29: 14796 | AH29: 636745 | AI29: 0 | AJ29: [2] | AK29: ["Saudi Arabia"] | AL29: ÿ£. ÿ≠ÿ≥ŸÜ ÿ®ŸÜ ÿ≥ÿπŸäÿØ | AN29: YH2L | AO29: 20251216

Sheet f_user_reaction_70690
A1: course_session_id | B1: room_id | C1: user_id | D1: event_datetime | E1: session_slide_id_reaction_made | F1: session_slide_id | G1: emotion | H1: part_of_activity | I1: total_reactions | J1: dt
A2: 70690 | B2: 54332 | C2: 647306 | D2: 46007.249 | E2: 1396622 | F2: 1396622 | G2: skip | H2: 1 | I2: 1 | J2: 20251216
A3: 70690 | B3: 54332 | C3: 647433 | D3: 46007.236 | E3: 1396625 | F3: 1396625 | G3: stronger | H3: 1 | I3: 1 | J3: 20251216
A4: 70690 | B4: 54332 | C4: 648959 | D4: 46007.25 | E4: 1396622 | F4: 1396622 | G4: loved | H4: 1 | I4: 1 | J4: 20251216
A5: 70690 | B5: 54332 | C5: 651452 | D5: 46007.243 | E5: 1396624 | F5: 1396624 | G5: stronger | H5: 1 | I5: 1 | J5: 20251216
A6: 70690 | B6: 54332 | C6: 652934 | D6: 46007.23 | E6: 1396599 | G6: loved | H6: 0 | I6: 1 | J6: 20251216
A7: 70690 | B7: 54332 | C7: 648953 | D7: 46007.253 | E7: 1396622 | F7: 1396622 | G7: loved | H7: 1 | I7: 1 | J7: 20251216
A8: 70690 | B8: 54332 | C8: 647748 | D8: 46007.23 | E8: 1396599 | G8: skip | H8: 0 | I8: 1 | J8: 20251216
A9: 70690 | B9: 54332 | C9: 657525 | D9: 46007.245 | E9: 1396623 | F9: 1396623 | G9: skip | H9: 1 | I9: 1 | J9: 20251216
A10: 70690 | B10: 54332 | C10: 647404 | D10: 46007.244 | E10: 1396624 | F10: 1396624 | G10: loved | H10: 1 | I10: 1 | J10: 20251216
A11: 70690 | B11: 54332 | C11: 647496 | D11: 46007.236 | E11: 1396625 | F11: 1396625 | G11: skip | H11: 1 | I11: 1 | J11: 20251216
A12: 70690 | B12: 54332 | C12: 647504 | D12: 46007.235 | E12: 1396625 | F12: 1396625 | G12: skip | H12: 0 | I12: 1 | J12: 20251216
A13: 70690 | B13: 54332 | C13: 652958 | D13: 46007.243 | E13: 1396624 | F13: 1396624 | G13: skip | H13: 1 | I13: 1 | J13: 20251216
A14: 70690 | B14: 54332 | C14: 648953 | D14: 46007.236 | E14: 1396625 | F14: 1396625 | G14: loved | H14: 1 | I14: 1 | J14: 20251216
A15: 70690 | B15: 54332 | C15: 648951 | D15: 46007.257 | E15: 1396621 | F15: 1396621 | G15: stronger | H15: 1 | I15: 1 | J15: 20251216
A16: 70690 | B16: 54332 | C16: 652934 | D16: 46007.245 | E16: 1396623 | F16: 1396623 | G16: stronger | H16: 1 | I16: 1 | J16: 20251216
A17: 70690 | B17: 54332 | C17: 652940 | D17: 46007.249 | E17: 1396622 | F17: 1396622 | G17: skip | H17: 1 | I17: 1 | J17: 20251216
A18: 70690 | B18: 54332 | C18: 647748 | D18: 46007.244 | E18: 1396624 | F18: 1396624 | G18: skip | H18: 1 | I18: 1 | J18: 20251216
A19: 70690 | B19: 54332 | C19: 648959 | D19: 46007.244 | E19: 1396608 | G19: loved | H19: 0 | I19: 1 | J19: 20251216
A20: 70690 | B20: 54332 | C20: 647411 | D20: 46007.23 | E20: 1396599 | G20: loved | H20: 0 | I20: 1 | J20: 20251216
A21: 70690 | B21: 54332 | C21: 647748 | D21: 46007.245 | E21: 1396623 | F21: 1396623 | G21: skip | H21: 1 | I21: 1 | J21: 20251216
A22: 70690 | B22: 54332 | C22: 652934 | D22: 46007.236 | E22: 1396625 | F22: 1396625 | G22: loved | H22: 1 | I22: 1 | J22: 20251216
A23: 70690 | B23: 54332 | C23: 648953 | D23: 46007.231 | E23: 1396599 | G23: loved | H23: 0 | I23: 1 | J23: 20251216
A24: 70690 | B24: 54332 | C24: 657525 | D24: 46007.243 | E24: 1396624 | F24: 1396624 | G24: skip | H24: 1 | I24: 1 | J24: 20251216
A25: 70690 | B25: 54332 | C25: 651452 | D25: 46007.236 | E25: 1396625 | F25: 1396625 | G25: stronger | H25: 1 | I25: 1 | J25: 20251216
A26: 70690 | B26: 54332 | C26: 647404 | D26: 46007.23 | E26: 1396599 | G26: loved | H26: 0 | I26: 1 | J26: 20251216
A27: 70690 | B27: 54332 | C27: 647306 | D27: 46007.257 | E27: 1396621 | F27: 1396621 | G27: loved | H27: 1 | I27: 1 | J27: 20251216
A28: 70690 | B28: 54332 | C28: 647748 | D28: 46007.236 | E28: 1396625 | F28: 1396625 | G28: skip | H28: 1 | I28: 1 | J28: 20251216
A29: 70690 | B29: 54332 | C29: 648986 | D29: 46007.251 | E29: 1396622 | F29: 1396622 | G29: skip | H29: 1 | I29: 1 | J29: 20251216
A30: 70690 | B30: 54332 | C30: 651452 | D30: 46007.249 | E30: 1396622 | F30: 1396622 | G30: stronger | H30: 1 | I30: 1 | J30: 20251216
A31: 70690 | B31: 54332 | C31: 647433 | D31: 46007.249 | E31: 1396622 | F31: 1396622 | G31: stronger | H31: 1 | I31: 1 | J31: 20251216
A32: 70690 | B32: 54332 | C32: 648986 | D32: 46007.236 | E32: 1396625 | F32: 1396625 | G32: skip | H32: 1 | I32: 1 | J32: 20251216
A33: 70690 | B33: 54332 | C33: 651452 | D33: 46007.257 | E33: 1396621 | F33: 1396621 | G33: stronger | H33: 1 | I33: 1 | J33: 20251216
A34: 70690 | B34: 54332 | C34: 647426 | D34: 46007.236 | E34: 1396625 | F34: 1396625 | G34: loved | H34: 1 | I34: 1 | J34: 20251216
A35: 70690 | B35: 54332 | C35: 651452 | D35: 46007.245 | E35: 1396623 | F35: 1396623 | G35: stronger | H35: 1 | I35: 1 | J35: 20251216
A36: 70690 | B36: 54332 | C36: 647404 | D36: 46007.247 | E36: 1396623 | F36: 1396623 | G36: loved | H36: 0 | I36: 1 | J36: 20251216
A37: 70690 | B37: 54332 | C37: 647404 | D37: 46007.25 | E37: 1396622 | F37: 1396622 | G37: loved | H37: 1 | I37: 1 | J37: 20251216
A38: 70690 | B38: 54332 | C38: 647295 | D38: 46007.24 | E38: 1396618 | F38: 1396625 | G38: loved | H38: 1 | I38: 1 | J38: 20251216
A39: 70690 | B39: 54332 | C39: 652929 | D39: 46007.238 | E39: 1396605 | F39: 1396625 | G39: skip | H39: 1 | I39: 1 | J39: 20251216
A40: 70690 | B40: 54332 | C40: 647411 | D40: 46007.231 | E40: 1396599 | G40: confused | H40: 0 | I40: 5 | J40: 20251216
...

Sheet f_user_poll_70690
A1: attempt_id | B1: poll_type | C1: poll_type_2 | D1: poll_id | E1: poll_source | F1: course_id | G1: course_session_id | H1: on_demand_session_id | I1: evaluation_id | J1: classroom_activity_id | K1: is_course_session_deleted | L1: poll_answered | M1: poll_seen | N1: user_id | O1: question_type | P1: question_id | Q1: question_text | R1: question_image_flag | S1: question_format | T1: show_correct_answer | U1: choice_type | V1: selected_choice_id | W1: submitted_choice_text | X1: correct_choice_id | Y1: is_correct_answer | Z1: poll_start_time | AA1: poll_end_time | AB1: poll_duration | AC1: total_choices_selected | AD1: creator_id | AE1: is_poll_deleted | AF1: poll_created_at | AG1: poll_updated_at | AH1: choice_submitted_at | AI1: rn
A2: mcq15195867 | B2: mcq | C2: EXIT_TICKET | D2: 342115 | E2: course session | F2: 14796 | G2: 70690 | J2: 148836 | K2: 0 | L2: 1 | M2: 1 | N2: 647404 | O2: has correct answer | P2: 18098 | Q2: ŸÖÿ≥ÿ™ÿ∑ŸäŸÑ ÿØÿßÿÆŸÑŸá Ÿ¶ ÿØŸàÿßÿ¶ÿ± ŸÖÿ™ÿ∑ÿßÿ®ŸÇÿ© ÿå ÿ£Ÿàÿ¨ÿØ ŸÇÿ∑ÿ± ÿßŸÑÿØÿßÿ¶ÿ±ÿ© ÿü | R2: 1 | S2: image and text | T2: 0 | U2: MCQ | V2: 91485 | X2: 91485 | Y2: 1 | Z2: 46007.26 | AA2: 46007.26 | AB2: 17 | AC2: 1 | AD2: 557612 | AE2: 0 | AF2: 46002.441 | AG2: 46002.441 | AH2: 46007.26 | AI2: 1
A3: mcq15195993 | B3: mcq | C3: EXIT_TICKET | D3: 342115 | E3: course session | F3: 14796 | G3: 70690 | J3: 148836 | K3: 0 | L3: 1 | M3: 1 | N3: 648959 | O3: has correct answer | P3: 18098 | Q3: ŸÖÿ≥ÿ™ÿ∑ŸäŸÑ ÿØÿßÿÆŸÑŸá Ÿ¶ ÿØŸàÿßÿ¶ÿ± ŸÖÿ™ÿ∑ÿßÿ®ŸÇÿ© ÿå ÿ£Ÿàÿ¨ÿØ ŸÇÿ∑ÿ± ÿßŸÑÿØÿßÿ¶ÿ±ÿ© ÿü | R3: 1 | S3: image and text | T3: 0 | U3: MCQ | V3: 91485 | X3: 91485 | Y3: 1 | Z3: 46007.261 | AA3: 46007.261 | AB3: 12 | AC3: 3 | AD3: 557612 | AE3: 0 | AF3: 46002.441 | AG3: 46002.441 | AH3: 46007.261 | AI3: 1 | AL3: 77 | AM3: poll_type_2 | AN3: (All)
A4: mcq15195818 | B4: mcq | C4: EXIT_TICKET | D4: 342115 | E4: course session | F4: 14796 | G4: 70690 | J4: 148836 | K4: 0 | L4: 1 | M4: 1 | N4: 647306 | O4: has correct answer | P4: 18098 | Q4: ŸÖÿ≥ÿ™ÿ∑ŸäŸÑ ÿØÿßÿÆŸÑŸá Ÿ¶ ÿØŸàÿßÿ¶ÿ± ŸÖÿ™ÿ∑ÿßÿ®ŸÇÿ© ÿå ÿ£Ÿàÿ¨ÿØ ŸÇÿ∑ÿ± ÿßŸÑÿØÿßÿ¶ÿ±ÿ© ÿü | R4: 1 | S4: image and text | T4: 0 | U4: MCQ | V4: 89471 | X4: 91485 | Y4: 0 | Z4: 46007.26 | AA4: 46007.26 | AB4: 27 | AC4: 1 | AD4: 557612 | AE4: 0 | AF4: 46002.441 | AG4: 46002.441 | AH4: 46007.26 | AI4: 1
A5: mcq15195820 | B5: mcq | C5: EXIT_TICKET | D5: 342115 | E5: course session | F5: 14796 | G5: 70690 | J5: 148836 | K5: 0 | L5: 1 | M5: 1 | N5: 647426 | O5: has correct answer | P5: 18098 | Q5: ŸÖÿ≥ÿ™ÿ∑ŸäŸÑ ÿØÿßÿÆŸÑŸá Ÿ¶ ÿØŸàÿßÿ¶ÿ± ŸÖÿ™ÿ∑ÿßÿ®ŸÇÿ© ÿå ÿ£Ÿàÿ¨ÿØ ŸÇÿ∑ÿ± ÿßŸÑÿØÿßÿ¶ÿ±ÿ© ÿü | R5: 1 | S5: image and text | T5: 0 | U5: MCQ | V5: 88112 | X5: 91485 | Y5: 0 | Z5: 46007.26 | AA5: 46007.26 | AB5: 10 | AC5: 1 | AD5: 557612 | AE5: 0 | AF5: 46002.441 | AG5: 46002.441 | AH5: 46007.26 | AI5: 1 | AM5: Row Labels | AN5: Sum of is_correct_answer | AO5: Sum of poll_answered | AP5: Count of user_id
A6: mcq15195870 | B6: mcq | C6: EXIT_TICKET | D6: 342115 | E6: course session | F6: 14796 | G6: 70690 | J6: 148836 | K6: 0 | L6: 1 | M6: 1 | N6: 657525 | O6: has correct answer | P6: 18098 | Q6: ŸÖÿ≥ÿ™ÿ∑ŸäŸÑ ÿØÿßÿÆŸÑŸá Ÿ¶ ÿØŸàÿßÿ¶ÿ± ŸÖÿ™ÿ∑ÿßÿ®ŸÇÿ© ÿå ÿ£Ÿàÿ¨ÿØ ŸÇÿ∑ÿ± ÿßŸÑÿØÿßÿ¶ÿ±ÿ© ÿü | R6: 1 | S6: image and text | T6: 0 | U6: MCQ | V6: 91485 | X6: 91485 | Y6: 1 | Z6: 46007.26 | AA6: 46007.26 | AB6: 43 | AC6: 1 | AD6: 557612 | AE6: 0 | AF6: 46002.441 | AG6: 46002.441 | AH6: 46007.26 | AI6: 1 | AM6: 148841 | AN6: 3 | AO6: 12 | AP6: 17 | AQ6: 0.17647059 | AS6: #REF! | AT6: #REF!
A7: mcq15195862 | B7: mcq | C7: EXIT_TICKET | D7: 342115 | E7: course session | F7: 14796 | G7: 70690 | J7: 148836 | K7: 0 | L7: 1 | M7: 1 | N7: 647748 | O7: has correct answer | P7: 18098 | Q7: ŸÖÿ≥ÿ™ÿ∑ŸäŸÑ ÿØÿßÿÆŸÑŸá Ÿ¶ ÿØŸàÿßÿ¶ÿ± ŸÖÿ™ÿ∑ÿßÿ®ŸÇÿ© ÿå ÿ£Ÿàÿ¨ÿØ ŸÇÿ∑ÿ± ÿßŸÑÿØÿßÿ¶ÿ±ÿ© ÿü | R7: 1 | S7: image and text | T7: 0 | U7: MCQ | V7: 91485 | X7: 91485 | Y7: 1 | Z7: 46007.26 | AA7: 46007.26 | AB7: 20 | AC7: 4 | AD7: 557612 | AE7: 0 | AF7: 46002.441 | AG7: 46002.441 | AH7: 46007.26 | AI7: 1 | AM7: 148840 | AN7: 7 | AO7: 11 | AP7: 18 | AT7: #REF!
A8: mcq15195924 | B8: mcq | C8: EXIT_TICKET | D8: 342115 | E8: course session | F8: 14796 | G8: 70690 | J8: 148836 | K8: 0 | L8: 1 | M8: 1 | N8: 648953 | O8: has correct answer | P8: 18098 | Q8: ŸÖÿ≥ÿ™ÿ∑ŸäŸÑ ÿØÿßÿÆŸÑŸá Ÿ¶ ÿØŸàÿßÿ¶ÿ± ŸÖÿ™ÿ∑ÿßÿ®ŸÇÿ© ÿå ÿ£Ÿàÿ¨ÿØ ŸÇÿ∑ÿ± ÿßŸÑÿØÿßÿ¶ÿ±ÿ© ÿü | R8: 1 | S8: image and text | T8: 0 | U8: MCQ | V8: 83110 | X8: 91485 | Y8: 0 | Z8: 46007.26 | AA8: 46007.26 | AB8: 1 | AC8: 1 | AD8: 557612 | AE8: 0 | AF8: 46002.441 | AG8: 46002.441 | AH8: 46007.26 | AI8: 1 | AM8: 148839 | AN8: 5 | AO8: 14 | AP8: 19 | AT8: #REF!
A9: mcq15196018 | B9: mcq | C9: EXIT_TICKET | D9: 342115 | E9: course session | F9: 14796 | G9: 70690 | J9: 148836 | K9: 0 | L9: 1 | M9: 1 | N9: 648986 | O9: has correct answer | P9: 18098 | Q9: ŸÖÿ≥ÿ™ÿ∑ŸäŸÑ ÿØÿßÿÆŸÑŸá Ÿ¶ ÿØŸàÿßÿ¶ÿ± ŸÖÿ™ÿ∑ÿßÿ®ŸÇÿ© ÿå ÿ£Ÿàÿ¨ÿØ ŸÇÿ∑ÿ± ÿßŸÑÿØÿßÿ¶ÿ±ÿ© ÿü | R9: 1 | S9: image and text | T9: 0 | U9: MCQ | V9: 91485 | X9: 91485 | Y9: 1 | Z9: 46007.26 | AA9: 46007.262 | AB9: 237 | AC9: 2 | AD9: 557612 | AE9: 0 | AF9: 46002.441 | AG9: 46002.441 | AH9: 46007.262 | AI9: 1 | AM9: 148838 | AN9: 10 | AO9: 14 | AP9: 20
A10: mcq15195960 | B10: mcq | C10: EXIT_TICKET | D10: 342115 | E10: course session | F10: 14796 | G10: 70690 | J10: 148836 | K10: 0 | L10: 1 | M10: 1 | N10: 647739 | O10: has correct answer | P10: 18098 | Q10: ŸÖÿ≥ÿ™ÿ∑ŸäŸÑ ÿØÿßÿÆŸÑŸá Ÿ¶ ÿØŸàÿßÿ¶ÿ± ŸÖÿ™ÿ∑ÿßÿ®ŸÇÿ© ÿå ÿ£Ÿàÿ¨ÿØ ŸÇÿ∑ÿ± ÿßŸÑÿØÿßÿ¶ÿ±ÿ© ÿü | R10: 1 | S10: image and text | T10: 0 | U10: MCQ | V10: 91485 | X10: 91485 | Y10: 1 | Z10: 46007.26 | AA10: 46007.26 | AB10: 11 | AC10: 1 | AD10: 557612 | AE10: 0 | AF10: 46002.441 | AG10: 46002.441 | AH10: 46007.26 | AI10: 1 | AM10: 148837 | AN10: 21 | AO10: 85 | AP10: 93
A11: mcq15195814 | B11: mcq | C11: EXIT_TICKET | D11: 342115 | E11: course session | F11: 14796 | G11: 70690 | J11: 148836 | K11: 0 | L11: 1 | M11: 1 | N11: 647433 | O11: has correct answer | P11: 18098 | Q11: ŸÖÿ≥ÿ™ÿ∑ŸäŸÑ ÿØÿßÿÆŸÑŸá Ÿ¶ ÿØŸàÿßÿ¶ÿ± ŸÖÿ™ÿ∑ÿßÿ®ŸÇÿ© ÿå ÿ£Ÿàÿ¨ÿØ ŸÇÿ∑ÿ± ÿßŸÑÿØÿßÿ¶ÿ±ÿ© ÿü | R11: 1 | S11: image and text | T11: 0 | U11: MCQ | V11: 88112 | X11: 91485 | Y11: 0 | Z11: 46007.26 | AA11: 46007.26 | AB11: 38 | AC11: 1 | AD11: 557612 | AE11: 0 | AF11: 46002.441 | AG11: 46002.441 | AH11: 46007.26 | AI11: 1 | AM11: 148836 | AN11: 31 | AO11: 58 | AP11: 64
A12: mcq15195830 | B12: mcq | C12: EXIT_TICKET | D12: 342115 | E12: course session | F12: 14796 | G12: 70690 | J12: 148836 | K12: 0 | L12: 1 | M12: 1 | N12: 651452 | O12: has correct answer | P12: 18098 | Q12: ŸÖÿ≥ÿ™ÿ∑ŸäŸÑ ÿØÿßÿÆŸÑŸá Ÿ¶ ÿØŸàÿßÿ¶ÿ± ŸÖÿ™ÿ∑ÿßÿ®ŸÇÿ© ÿå ÿ£Ÿàÿ¨ÿØ ŸÇÿ∑ÿ± ÿßŸÑÿØÿßÿ¶ÿ±ÿ© ÿü | R12: 1 | S12: image and text | T12: 0 | U12: MCQ | V12: 91485 | X12: 91485 | Y12: 1 | Z12: 46007.26 | AA12: 46007.26 | AB12: 9 | AC12: 1 | AD12: 557612 | AE12: 0 | AF12: 46002.441 | AG12: 46002.441 | AH12: 46007.26 | AI12: 1 | AM12: Grand Total | AN12: 77 | AO12: 194 | AP12: 231 | AQ12: 0.33333333
A13: mcq15195899 | B13: mcq | C13: EXIT_TICKET | D13: 342115 | E13: course session | F13: 14796 | G13: 70690 | J13: 148836 | K13: 0 | L13: 1 | M13: 1 | N13: 647499 | O13: has correct answer | P13: 18098 | Q13: ŸÖÿ≥ÿ™ÿ∑ŸäŸÑ ÿØÿßÿÆŸÑŸá Ÿ¶ ÿØŸàÿßÿ¶ÿ± ŸÖÿ™ÿ∑ÿßÿ®ŸÇÿ© ÿå ÿ£Ÿàÿ¨ÿØ ŸÇÿ∑ÿ± ÿßŸÑÿØÿßÿ¶ÿ±ÿ© ÿü | R13: 1 | S13: image and text | T13: 0 | U13: MCQ | V13: 91485 | X13: 91485 | Y13: 1 | Z13: 46007.26 | AA13: 46007.26 | AB13: 9 | AC13: 1 | AD13: 557612 | AE13: 0 | AF13: 46002.441 | AG13: 46002.441 | AH13: 46007.26 | AI13: 1
A14: mcq15195821 | B14: mcq | C14: EXIT_TICKET | D14: 342115 | E14: course session | F14: 14796 | G14: 70690 | J14: 148836 | K14: 0 | L14: 0 | M14: 0 | N14: 652933 | O14: has correct answer | P14: 18098 | Q14: ŸÖÿ≥ÿ™ÿ∑ŸäŸÑ ÿØÿßÿÆŸÑŸá Ÿ¶ ÿØŸàÿßÿ¶ÿ± ŸÖÿ™ÿ∑ÿßÿ®ŸÇÿ© ÿå ÿ£Ÿàÿ¨ÿØ ŸÇÿ∑ÿ± ÿßŸÑÿØÿßÿ¶ÿ±ÿ© ÿü | R14: 1 | S14: image and text | T14: 0 | U14: MCQ | V14: -1 | X14: 91485 | Z14: 46007.26 | AA14: 46007.26 | AC14: 0 | AD14: 557612 | AE14: 0 | AF14: 46002.441 | AG14: 46002.441 | AI14: 1
A15: mcq15195817 | B15: mcq | C15: EXIT_TICKET | D15: 342115 | E15: course session | F15: 14796 | G15: 70690 | J15: 148836 | K15: 0 | L15: 0 | M15: 0 | N15: 652938 | O15: has correct answer | P15: 18098 | Q15: ŸÖÿ≥ÿ™ÿ∑ŸäŸÑ ÿØÿßÿÆŸÑŸá Ÿ¶ ÿØŸàÿßÿ¶ÿ± ŸÖÿ™ÿ∑ÿßÿ®ŸÇÿ© ÿå ÿ£Ÿàÿ¨ÿØ ŸÇÿ∑ÿ± ÿßŸÑÿØÿßÿ¶ÿ±ÿ© ÿü | R15: 1 | S15: image and text | T15: 0 | U15: MCQ | V15: -1 | X15: 91485 | Z15: 46007.26 | AA15: 46007.26 | AC15: 0 | AD15: 557612 | AE15: 0 | AF15: 46002.441 | AG15: 46002.441 | AI15: 1
A16: mcq15195815 | B16: mcq | C16: EXIT_TICKET | D16: 342115 | E16: course session | F16: 14796 | G16: 70690 | J16: 148836 | K16: 0 | L16: 1 | M16: 1 | N16: 647496 | O16: has correct answer | P16: 18098 | Q16: ŸÖÿ≥ÿ™ÿ∑ŸäŸÑ ÿØÿßÿÆŸÑŸá Ÿ¶ ÿØŸàÿßÿ¶ÿ± ŸÖÿ™ÿ∑ÿßÿ®ŸÇÿ© ÿå ÿ£Ÿàÿ¨ÿØ ŸÇÿ∑ÿ± ÿßŸÑÿØÿßÿ¶ÿ±ÿ© ÿü | R16: 1 | S16: image and text | T16: 0 | U16: MCQ | V16: 91485 | X16: 91485 | Y16: 1 | Z16: 46007.26 | AA16: 46007.26 | AB16: 34 | AC16: 1 | AD16: 557612 | AE16: 0 | AF16: 46002.441 | AG16: 46002.441 | AH16: 46007.26 | AI16: 1
A17: mcq15195833 | B17: mcq | C17: EXIT_TICKET | D17: 342115 | E17: course session | F17: 14796 | G17: 70690 | J17: 148836 | K17: 0 | L17: 1 | M17: 1 | N17: 648951 | O17: has correct answer | P17: 18098 | Q17: ŸÖÿ≥ÿ™ÿ∑ŸäŸÑ ÿØÿßÿÆŸÑŸá Ÿ¶ ÿØŸàÿßÿ¶ÿ± ŸÖÿ™ÿ∑ÿßÿ®ŸÇÿ© ÿå ÿ£Ÿàÿ¨ÿØ ŸÇÿ∑ÿ± ÿßŸÑÿØÿßÿ¶ÿ±ÿ© ÿü | R17: 1 | S17: image and text | T17: 0 | U17: MCQ | V17: 88112 | X17: 91485 | Y17: 0 | Z17: 46007.26 | AA17: 46007.26 | AB17: 39 | AC17: 1 | AD17: 557612 | AE17: 0 | AF17: 46002.441 | AG17: 46002.441 | AH17: 46007.26 | AI17: 1
A18: mcq15195836 | B18: mcq | C18: EXIT_TICKET | D18: 342115 | E18: course session | F18: 14796 | G18: 70690 | J18: 148836 | K18: 0 | L18: 1 | M18: 1 | N18: 652934 | O18: has correct answer | P18: 18098 | Q18: ŸÖÿ≥ÿ™ÿ∑ŸäŸÑ ÿØÿßÿÆŸÑŸá Ÿ¶ ÿØŸàÿßÿ¶ÿ± ŸÖÿ™ÿ∑ÿßÿ®ŸÇÿ© ÿå ÿ£Ÿàÿ¨ÿØ ŸÇÿ∑ÿ± ÿßŸÑÿØÿßÿ¶ÿ±ÿ© ÿü | R18: 1 | S18: image and text | T18: 0 | U18: MCQ | V18: 91485 | X18: 91485 | Y18: 1 | Z18: 46007.26 | AA18: 46007.26 | AB18: 1 | AC18: 1 | AD18: 557612 | AE18: 0 | AF18: 46002.441 | AG18: 46002.441 | AH18: 46007.26 | AI18: 1
A19: mcq15193754 | B19: mcq | C19: TEAM_EXERCISE | D19: 342120 | E19: course session | F19: 14796 | G19: 70690 | J19: 148837 | K19: 0 | L19: 1 | M19: 1 | N19: 647748 | O19: has correct answer | P19: 367083 | Q19: ÿ£Ÿàÿ¨ÿØ ŸÖÿ≥ÿßÿ≠ÿ© ÿßŸÑÿØÿßÿ¶ÿ±ÿ©&nbsp; | R19: 1 | S19: image and text | T19: 1 | U19: MCQ | V19: 1428917 | X19: 1428917 | Y19: 1 | Z19: 46007.253 | AA19: 46007.253 | AB19: 39 | AC19: 1 | AD19: 557612 | AE19: 0 | AF19: 46002.441 | AG19: 46002.441 | AH19: 46007.253 | AI19: 1
A20: mcq15194043 | B20: mcq | C20: TEAM_EXERCISE | D20: 342120 | E20: course session | F20: 14796 | G20: 70690 | J20: 148837 | K20: 0 | L20: 1 | M20: 1 | N20: 648951 | O20: has correct answer | P20: 367083 | Q20: ÿ£Ÿàÿ¨ÿØ ŸÖÿ≥ÿßÿ≠ÿ© ÿßŸÑÿØÿßÿ¶ÿ±ÿ©&nbsp; | R20: 1 | S20: image and text | T20: 1 | U20: MCQ | V20: 1428917 | X20: 1428917 | Y20: 1 | Z20: 46007.255 | AA20: 46007.255 | AB20: 13 | AC20: 1 | AD20: 557612 | AE20: 0 | AF20: 46002.441 | AG20: 46002.441 | AH20: 46007.255 | AI20: 1
A21: mcq15193723 | B21: mcq | C21: TEAM_EXERCISE | D21: 342120 | E21: course session | F21: 14796 | G21: 70690 | J21: 148837 | K21: 0 | L21: 1 | M21: 1 | N21: 647499 | O21: has correct answer | P21: 367083 | Q21: ÿ£Ÿàÿ¨ÿØ ŸÖÿ≥ÿßÿ≠ÿ© ÿßŸÑÿØÿßÿ¶ÿ±ÿ©&nbsp; | R21: 1 | S21: image and text | T21: 1 | U21: MCQ | V21: 1428916 | X21: 1428917 | Y21: 0 | Z21: 46007.253 | AA21: 46007.253 | AB21: 22 | AC21: 1 | AD21: 557612 | AE21: 0 | AF21: 46002.441 | AG21: 46002.441 | AH21: 46007.253 | AI21: 1
A22: mcq15193939 | B22: mcq | C22: TEAM_EXERCISE | D22: 342120 | E22: course session | F22: 14796 | G22: 70690 | J22: 148837 | K22: 0 | L22: 1 | M22: 1 | N22: 647426 | O22: has correct answer | P22: 367083 | Q22: ÿ£Ÿàÿ¨ÿØ ŸÖÿ≥ÿßÿ≠ÿ© ÿßŸÑÿØÿßÿ¶ÿ±ÿ©&nbsp; | R22: 1 | S22: image and text | T22: 1 | U22: MCQ | V22: 1428917 | X22: 1428917 | Y22: 1 | Z22: 46007.253 | AA22: 46007.254 | AB22: 98 | AC22: 6 | AD22: 557612 | AE22: 0 | AF22: 46002.441 | AG22: 46002.441 | AH22: 46007.254 | AI22: 1
A23: mcq15193868 | B23: mcq | C23: TEAM_EXERCISE | D23: 342120 | E23: course session | F23: 14796 | G23: 70690 | J23: 148837 | K23: 0 | L23: 1 | M23: 1 | N23: 647404 | O23: has correct answer | P23: 367083 | Q23: ÿ£Ÿàÿ¨ÿØ ŸÖÿ≥ÿßÿ≠ÿ© ÿßŸÑÿØÿßÿ¶ÿ±ÿ©&nbsp; | R23: 1 | S23: image and text | T23: 1 | U23: MCQ | V23: 1428917 | X23: 1428917 | Y23: 1 | Z23: 46007.253 | AA23: 46007.253 | AB23: 48 | AC23: 2 | AD23: 557612 | AE23: 0 | AF23: 46002.441 | AG23: 46002.441 | AH23: 46007.253 | AI23: 1
A24: mcq15193841 | B24: mcq | C24: TEAM_EXERCISE | D24: 342120 | E24: course session | F24: 14796 | G24: 70690 | J24: 148837 | K24: 0 | L24: 1 | M24: 1 | N24: 647306 | O24: has correct answer | P24: 367083 | Q24: ÿ£Ÿàÿ¨ÿØ ŸÖÿ≥ÿßÿ≠ÿ© ÿßŸÑÿØÿßÿ¶ÿ±ÿ©&nbsp; | R24: 1 | S24: image and text | T24: 1 | U24: MCQ | V24: 1428916 | X24: 1428917 | Y24: 0 | Z24: 46007.253 | AA24: 46007.254 | AB24: 49 | AC24: 1 | AD24: 557612 | AE24: 0 | AF24: 46002.441 | AG24: 46002.441 | AH24: 46007.254 | AI24: 1
A25: mcq15194266 | B25: mcq | C25: TEAM_EXERCISE | D25: 342120 | E25: course session | F25: 14796 | G25: 70690 | J25: 148837 | K25: 0 | L25: 1 | M25: 1 | N25: 652933 | O25: has correct answer | P25: 367083 | Q25: ÿ£Ÿàÿ¨ÿØ ŸÖÿ≥ÿßÿ≠ÿ© ÿßŸÑÿØÿßÿ¶ÿ±ÿ©&nbsp; | R25: 1 | S25: image and text | T25: 1 | U25: MCQ | V25: 1428915 | X25: 1428917 | Y25: 0 | Z25: 46007.256 | AA25: 46007.256 | AB25: 4 | AC25: 1 | AD25: 557612 | AE25: 0 | AF25: 46002.441 | AG25: 46002.441 | AH25: 46007.256 | AI25: 1
A26: mcq15193714 | B26: mcq | C26: TEAM_EXERCISE | D26: 342120 | E26: course session | F26: 14796 | G26: 70690 | J26: 148837 | K26: 0 | L26: 1 | M26: 1 | N26: 652934 | O26: has correct answer | P26: 367083 | Q26: ÿ£Ÿàÿ¨ÿØ ŸÖÿ≥ÿßÿ≠ÿ© ÿßŸÑÿØÿßÿ¶ÿ±ÿ©&nbsp; | R26: 1 | S26: image and text | T26: 1 | U26: MCQ | V26: 1428916 | X26: 1428917 | Y26: 0 | Z26: 46007.253 | AA26: 46007.253 | AB26: 11 | AC26: 1 | AD26: 557612 | AE26: 0 | AF26: 46002.441 | AG26: 46002.441 | AH26: 46007.253 | AI26: 1
A27: mcq15193778 | B27: mcq | C27: TEAM_EXERCISE | D27: 342120 | E27: course session | F27: 14796 | G27: 70690 | J27: 148837 | K27: 0 | L27: 1 | M27: 1 | N27: 652958 | O27: has correct answer | P27: 367083 | Q27: ÿ£Ÿàÿ¨ÿØ ŸÖÿ≥ÿßÿ≠ÿ© ÿßŸÑÿØÿßÿ¶ÿ±ÿ©&nbsp; | R27: 1 | S27: image and text | T27: 1 | U27: MCQ | V27: 1428915 | X27: 1428917 | Y27: 0 | Z27: 46007.253 | AA27: 46007.253 | AB27: 12 | AC27: 1 | AD27: 557612 | AE27: 0 | AF27: 46002.441 | AG27: 46002.441 | AH27: 46007.253 | AI27: 1
... A38: mcq15189225 | B38: mcq | C38: SECTION_CHECK | D38: 342127 | E38: course session | F38: 14796 | G38: 70690 | J38: 148841 | K38: 0 | L38: 1 | M38: 1 | N38: 647496 | O38: has correct answer | P38: 323256 | Q38: ÿ£Ÿàÿ¨ÿØ ŸÖÿ≠Ÿäÿ∑ ÿßŸÑŸÖÿ´ŸÑÿ´ ÿü | R38: 1 | S38: image and text | T38: 0 | U38: MCQ | V38: 1265052 | X38: 1265052 | Y38: 1 | Z38: 46007.235 | AA38: 46007.235 | AB38: 60 | AC38: 1 | AD38: 557612 | AE38: 0 | AF38: 46002.441 | AG38: 46002.441 | AH38: 46007.235 | AI38: 1
A39: mcq15189227 | B39: mcq | C39: SECTION_CHECK | D39: 342127 | E39: course session | F39: 14796 | G39: 70690 | J39: 148841 | K39: 0 | L39: 0 | M39: 0 | N39: 652938 | O39: has correct answer | P39: 323256 | Q39: ÿ£Ÿàÿ¨ÿØ ŸÖÿ≠Ÿäÿ∑ ÿßŸÑŸÖÿ´ŸÑÿ´ ÿü | R39: 1 | S39: image and text | T39: 0 | U39: MCQ | V39: -1 | X39: 1265052 | Z39: 46007.235 | AA39: 46007.235 | AC39: 0 | AD39: 557612 | AE39: 0 | AF39: 46002.441 | AG39: 46002.441 | AI39: 1
A40: mcq15189238 | B40: mcq | C40: SECTION_CHECK | D40: 342127 | E40: course session | F40: 14796 | G40: 70690 | J40: 148841 | K40: 0 | L40: 1 | M40: 1 | N40: 647504 | O40: has correct answer | P40: 323256 | Q40: ÿ£Ÿàÿ¨ÿØ ŸÖÿ≠Ÿäÿ∑ ÿßŸÑŸÖÿ´ŸÑÿ´ ÿü | R40: 1 | S40: image and text | T40: 0 | U40: MCQ | V40: 1265053 | X40: 1265052 | Y40: 0 | Z40: 46007.235 | AA40: 46007.235 | AB40: 60 | AC40: 1 | AD40: 557612 | AE40: 0 | AF40: 46002.441 | AG40: 46002.441 | AH40: 46007.235 | AI40: 1
A41: mcq15189315 | B41: mcq | C41: SECTION_CHECK | D41: 342127 | E41: course session | F41: 14796 | G41: 70690 | J41: 148841 | K41: 0 | L41: 1 | M41: 1 | N41: 648986 | O41: has correct answer | P41: 323256 | Q41: ÿ£Ÿàÿ¨ÿØ ŸÖÿ≠Ÿäÿ∑ ÿßŸÑŸÖÿ´ŸÑÿ´ ÿü | R41: 1 | S41: image and text | T41: 0 | U41: MCQ | V41: 1265051 | X41: 1265052 | Y41: 0 | Z41: 46007.235 | AA41: 46007.235 | AB41: 60 | AC41: 2 | AD41: 557612 | AE41: 0 | AF41: 46002.441 | AG41: 46002.441 | AH41: 46007.235 | AI41: 1
A42: mcq15189319 | B42: mcq | C42: SECTION_CHECK | D42: 342127 | E42: course session | F42: 14796 | G42: 70690 | J42: 148841 | K42: 0 | L42: 1 | M42: 1 | N42: 648959 | O42: has correct answer | P42: 323256 | Q42: ÿ£Ÿàÿ¨ÿØ ŸÖÿ≠Ÿäÿ∑ ÿßŸÑŸÖÿ´ŸÑÿ´ ÿü | R42: 1 | S42: image and text | T42: 0 | U42: MCQ | V42: 1265051 | X42: 1265052 | Y42: 0 | Z42: 46007.235 | AA42: 46007.235 | AB42: 60 | AC42: 4 | AD42: 557612 | AE42: 0 | AF42: 46002.441 | AG42: 46002.441 | AH42: 46007.235 | AI42: 1
A43: mcq15189228 | B43: mcq | C43: SECTION_CHECK | D43: 342127 | E43: course session | F43: 14796 | G43: 70690 | J43: 148841 | K43: 0 | L43: 0 | M43: 0 | N43: 647404 | O43: has correct answer | P43: 323256 | Q43: ÿ£Ÿàÿ¨ÿØ ŸÖÿ≠Ÿäÿ∑ ÿßŸÑŸÖÿ´ŸÑÿ´ ÿü | R43: 1 | S43: image and text | T43: 0 | U43: MCQ | V43: -1 | X43: 1265052 | Z43: 46007.235 | AA43: 46007.235 | AC43: 0 | AD43: 557612 | AE43: 0 | AF43: 46002.441 | AG43: 46002.441 | AI43: 1
A44: mcq15189229 | B44: mcq | C44: SECTION_CHECK | D44: 342127 | E44: course session | F44: 14796 | G44: 70690 | J44: 148841 | K44: 0 | L44: 0 | M44: 0 | N44: 652929 | O44: has correct answer | P44: 323256 | Q44: ÿ£Ÿàÿ¨ÿØ ŸÖÿ≠Ÿäÿ∑ ÿßŸÑŸÖÿ´ŸÑÿ´ ÿü | R44: 1 | S44: image and text | T44: 0 | U44: MCQ | V44: -1 | X44: 1265052 | Z44: 46007.235 | AA44: 46007.235 | AC44: 0 | AD44: 557612 | AE44: 0 | AF44: 46002.441 | AG44: 46002.441 | AI44: 1
A45: mcq15189233 | B45: mcq | C45: SECTION_CHECK | D45: 342127 | E45: course session | F45: 14796 | G45: 70690 | J45: 148841 | K45: 0 | L45: 0 | M45: 0 | N45: 648953 | O45: has correct answer | P45: 323256 | Q45: ÿ£Ÿàÿ¨ÿØ ŸÖÿ≠Ÿäÿ∑ ÿßŸÑŸÖÿ´ŸÑÿ´ ÿü | R45: 1 | S45: image and text | T45: 0 | U45: MCQ | V45: -1 | X45: 1265052 | Z45: 46007.235 | AA45: 46007.235 | AC45: 0 | AD45: 557612 | AE45: 0 | AF45: 46002.441 | AG45: 46002.441 | AI45: 1
A46: mcq15189236 | B46: mcq | C46: SECTION_CHECK | D46: 342127 | E46: course session | F46: 14796 | G46: 70690 | J46: 148841 | K46: 0 | L46: 0 | M46: 0 | N46: 647295 | O46: has correct answer | P46: 323256 | Q46: ÿ£Ÿàÿ¨ÿØ ŸÖÿ≠Ÿäÿ∑ ÿßŸÑŸÖÿ´ŸÑÿ´ ÿü | R46: 1 | S46: image and text | T46: 0 | U46: MCQ | V46: -1 | X46: 1265052 | Z46: 46007.235 | AA46: 46007.235 | AC46: 0 | AD46: 557612 | AE46: 0 | AF46: 46002.441 | AG46: 46002.441 | AI46: 1
A47: mcq15189317 | B47: mcq | C47: SECTION_CHECK | D47: 342127 | E47: course session | F47: 14796 | G47: 70690 | J47: 148841 | K47: 0 | L47: 1 | M47: 1 | N47: 647499 | O47: has correct answer | P47: 323256 | Q47: ÿ£Ÿàÿ¨ÿØ ŸÖÿ≠Ÿäÿ∑ ÿßŸÑŸÖÿ´ŸÑÿ´ ÿü | R47: 1 | S47: image and text | T47: 0 | U47: MCQ | V47: 1265054 | X47: 1265052 | Y47: 0 | Z47: 46007.235 | AA47: 46007.235 | AB47: 60 | AC47: 3 | AD47: 557612 | AE47: 0 | AF47: 46002.441 | AG47: 46002.441 | AH47: 46007.235 | AI47: 1
A48: mcq15189230 | B48: mcq | C48: SECTION_CHECK | D48: 342127 | E48: course session | F48: 14796 | G48: 70690 | J48: 148841 | K48: 0 | L48: 1 | M48: 1 | N48: 647426 | O48: has correct answer | P48: 323256 | Q48: ÿ£Ÿàÿ¨ÿØ ŸÖÿ≠Ÿäÿ∑ ÿßŸÑŸÖÿ´ŸÑÿ´ ÿü | R48: 1 | S48: image and text | T48: 0 | U48: MCQ | V48: 1265053 | X48: 1265052 | Y48: 0 | Z48: 46007.235 | AA48: 46007.235 | AB48: 60 | AC48: 1 | AD48: 557612 | AE48: 0 | AF48: 46002.441 | AG48: 46002.441 | AH48: 46007.235 | AI48: 1
A49: mcq15189224 | B49: mcq | C49: SECTION_CHECK | D49: 342127 | E49: course session | F49: 14796 | G49: 70690 | J49: 148841 | K49: 0 | L49: 1 | M49: 1 | N49: 647433 | O49: has correct answer | P49: 323256 | Q49: ÿ£Ÿàÿ¨ÿØ ŸÖÿ≠Ÿäÿ∑ ÿßŸÑŸÖÿ´ŸÑÿ´ ÿü | R49: 1 | S49: image and text | T49: 0 | U49: MCQ | V49: 1265052 | X49: 1265052 | Y49: 1 | Z49: 46007.235 | AA49: 46007.235 | AB49: 60 | AC49: 1 | AD49: 557612 | AE49: 0 | AF49: 46002.441 | AG49: 46002.441 | AH49: 46007.235 | AI49: 1
A50: mcq15189318 | B50: mcq | C50: SECTION_CHECK | D50: 342127 | E50: course session | F50: 14796 | G50: 70690 | J50: 148841 | K50: 0 | L50: 1 | M50: 1 | N50: 647411 | O50: has correct answer | P50: 323256 | Q50: ÿ£Ÿàÿ¨ÿØ ŸÖÿ≠Ÿäÿ∑ ÿßŸÑŸÖÿ´ŸÑÿ´ ÿü | R50: 1 | S50: image and text | T50: 0 | U50: MCQ | V50: 1265052 | X50: 1265052 | Y50: 1 | Z50: 46007.235 | AA50: 46007.235 | AB50: 60 | AC50: 4 | AD50: 557612 | AE50: 0 | AF50: 46002.441 | AG50: 46002.441 | AH50: 46007.235 | AI50: 1
...

Sheet d_classroom_activity_70690
A1: activity_id | B1: course_session_id | C1: session_class_type | D1: session_slide_id | E1: type | F1: start_time | G1: end_time | H1: activity_happened | I1: created_at | J1: planned_duration | K1: duration | L1: mcq_ids | M1: question_ids | N1: room_ids | O1: total_mcqs | P1: creator_id | Q1: mcq_types
A2: 148841 | B2: 70690 | C2: LIVE_CLASS | D2: 1396625 | E2: SECTION_CHECK | F2: 46007.235 | G2: 46007.236 | H2: 1 | I2: 46002.441 | J2: 60 | K2: 65 | L2: [342127] | M2: [323256] | N2: [54332] | O2: 1 | P2: 557612 | Q2: ["MCQ"]
A3: 148837 | B3: 70690 | C3: LIVE_CLASS | D3: 1396621 | E3: TEAM_EXERCISE | F3: 46007.253 | G3: 46007.256 | H3: 1 | I3: 46002.441 | J3: 300 | K3: 309 | L3: [342123, 342119, 342120, 342121, 342122] | M3: [367083, 339665, 347331, 334117, 334118] | N3: [54332] | O3: 5 | P3: 557612 | Q3: ["MCQ"]
A4: 148836 | B4: 70690 | C4: LIVE_CLASS | D4: 1396620 | E4: EXIT_TICKET | F4: 46007.26 | G4: 46007.263 | H4: 1 | I4: 46002.441 | J4: 240 | K4: 243 | L4: [342115, 342116, 342117, 342118] | M4: [321509, 321830, 319911, 18098] | N4: [54332] | O4: 4 | P4: 557612 | Q4: ["MCQ"]
A5: 148839 | B5: 70690 | C5: LIVE_CLASS | D5: 1396623 | E5: SECTION_CHECK | F5: 46007.244 | G5: 46007.245 | H5: 1 | I5: 46002.441 | J5: 60 | K5: 66 | L5: [342125] | M5: [339211] | N5: [54332] | O5: 1 | P5: 557612 | Q5: ["MCQ"]
A6: 148840 | B6: 70690 | C6: LIVE_CLASS | D6: 1396624 | E6: SECTION_CHECK | F6: 46007.242 | G6: 46007.243 | H6: 1 | I6: 46002.441 | J6: 60 | K6: 65 | L6: [342126] | M6: [339432] | N6: [54332] | O6: 1 | P6: 557612 | Q6: ["MCQ"]
A7: 148838 | B7: 70690 | C7: LIVE_CLASS | D7: 1396622 | E7: SECTION_CHECK | F7: 46007.249 | G7: 46007.249 | H7: 1 | I7: 46002.441 | J7: 60 | K7: 63 | L7: [342124] | M7: [322117] | N7: [54332] | O7: 1 | P7: 557612 | Q7: ["MCQ"]

Sheet chats_70690
A1: op | B1: timestamp_dms | C1: _id | D1: message_id | E1: message_text | F1: chat_id | G1: creator_id | H1: user_type | I1: course_session_id | J1: creator_name | K1: creator_avatar_url | L1: created_at_ms | M1: created_at_ts | N1: rn | O1: _doc
A2: I | B2: 46007.231 | C2: 6940eeceb7e9a1769e0962e8 | D2: 77e7d25d-21fe-45e2-801d-5211ac21f15f | E2: ÿßŸÑÿµŸàÿ™ ŸäŸÇÿ∑ÿπ | F2: 731f4273-a000-45da-b73c-049e6b683305 | G2: 652934 | H2: STUDENT | I2: 70690 | J2: ÿπÿ®ÿØÿßŸÑŸÑŸá ÿßŸÑŸáÿßÿ¨ÿ±Ÿä | L2: 1765863118082 | M2: 46007.231 | N2: 1 | O2: { "_id" : { "$oid" : "6940eeceb7e9a1769e0962e8" }, "id" : "77e7d25d-21fe-45e2-801d-5211ac21f15f", "text" : "ÿßŸÑÿµŸàÿ™ ŸäŸÇÿ∑ÿπ", "chat_id" : "731f4273-a000-45da-b73c-049e6b683305", "creator_id" : 652934, "user_type" : "STUDENT", "metadata" : { "courseSessionId" : 70690 }, "creator_metadata" : { "name" : "ÿπÿ®ÿØÿßŸÑŸÑŸá ÿßŸÑŸáÿßÿ¨ÿ±Ÿä", "avatarUrl" : { "url" : "https://cdn.studyatnoon.com/public/school_student/652934/fd4bf2e8-3c23-4481-b3e2-2d9e010383ce_thumbnail.jpeg" } }, "created_at" : { "$date" : 1765863118082 }, "_class" : "com.noon.noon2.entity.chat.ChatMessage" }
A3: I | B3: 46007.244 | C3: 6940f33db7e9a1769e09805f | D3: afe5411a-a1d2-407b-8c1f-371a2b78b3a7 | E3: ÿßŸäŸá | F3: 731f4273-a000-45da-b73c-049e6b683305 | G3: 647411 | H3: STUDENT | I3: 70690 | J3: ŸÅÿßÿ±ÿ≥ ÿπŸàÿ∂Ÿá | L3: 1765864253761 | M3: 46007.244 | N3: 1 | O3: { "_id" : { "$oid" : "6940f33db7e9a1769e09805f" }, "id" : "afe5411a-a1d2-407b-8c1f-371a2b78b3a7", "text" : "ÿßŸäŸá", "chat_id" : "731f4273-a000-45da-b73c-049e6b683305", "creator_id" : 647411, "user_type" : "STUDENT", "metadata" : { "courseSessionId" : 70690 }, "creator_metadata" : { "name" : "ŸÅÿßÿ±ÿ≥ ÿπŸàÿ∂Ÿá", "avatarUrl" : { "url" : "https://cdn.studyatnoon.com/public/school_student/647411/79ee8fc4-175b-4e8f-a16a-22c46e72f4b1_thumbnail.jpeg" } }, "created_at" : { "$date" : 1765864253761 }, "_class" : "com.noon.noon2.entity.chat.ChatMessage" }
A4: I | B4: 46007.258 | C4: 6940f807b7e9a1769e09af5a | D4: d1809ee3-77a5-4df4-87cb-453c9ae7dd9b | E4: ŸÅŸáŸÖÿ™ | F4: 731f4273-a000-45da-b73c-049e6b683305 | G4: 648951 | H4: STUDENT | I4: 70690 | J4: ÿ•ÿ®ÿ±ÿßŸáŸäŸÖ ÿ®ŸÜ ÿØÿßŸäŸÑ | L4: 1765865479199 | M4: 46007.258 | N4: 1 | O4: { "_id" : { "$oid" : "6940f807b7e9a1769e09af5a" }, "id" : "d1809ee3-77a5-4df4-87cb-453c9ae7dd9b", "text" : "ŸÅŸáŸÖÿ™", "chat_id" : "731f4273-a000-45da-b73c-049e6b683305", "creator_id" : 648951, "user_type" : "STUDENT", "metadata" : { "courseSessionId" : 70690 }, "creator_metadata" : { "name" : "ÿ•ÿ®ÿ±ÿßŸáŸäŸÖ ÿ®ŸÜ ÿØÿßŸäŸÑ", "avatarUrl" : { "url" : "https://cdn.non.sa/images/avatar/male/1.png" } }, "created_at" : { "$date" : 1765865479199 }, "_class" : "com.noon.noon2.entity.chat.ChatMessage" }
A5: I | B5: 46007.231 | C5: 6940eedfb7e9a1769e09632a | D5: c2f7180a-9063-419d-a485-e1a49c4176aa | E5: ŸÑÿß | F5: 731f4273-a000-45da-b73c-049e6b683305 | G5: 652934 | H5: STUDENT | I5: 70690 | J5: ÿπÿ®ÿØÿßŸÑŸÑŸá ÿßŸÑŸáÿßÿ¨ÿ±Ÿä | L5: 1765863135847 | M5: 46007.231 | N5: 1 | O5: { "_id" : { "$oid" : "6940eedfb7e9a1769e09632a" }, "id" : "c2f7180a-9063-419d-a485-e1a49c4176aa", "text" : "ŸÑÿß", "chat_id" : "731f4273-a000-45da-b73c-049e6b683305", "creator_id" : 652934, "user_type" : "STUDENT", "metadata" : { "courseSessionId" : 70690 }, "creator_metadata" : { "name" : "ÿπÿ®ÿØÿßŸÑŸÑŸá ÿßŸÑŸáÿßÿ¨ÿ±Ÿä", "avatarUrl" : { "url" : "https://cdn.studyatnoon.com/public/school_student/652934/fd4bf2e8-3c23-4481-b3e2-2d9e010383ce_thumbnail.jpeg" } }, "created_at" : { "$date" : 1765863135847 }, "_class" : "com.noon.noon2.entity.chat.ChatMessage" }
